Workbook
Name _01___04月___生産_計劃__對___實績: #REF!
Name _01___04月___生産_計劃__對___實績: #REF!
Name _01___04月___生産_計劃__對___實績: #REF!
Name _01_02월: #REF!
Name _01_02월: #REF!
Name _1_3_0Crite: #REF!
Name _1_3_0Crite: #REF!
Name _2_3_0Criteria: #REF!
Name _2_3_0Criteria: #REF!
Name _3G_0Extr: #REF!
Name _3G_0Extr: #REF!
Name _4G_0Extract: #REF!
Name _4G_0Extract: #REF!
Name _Order1: 0
Name _Order2: 0
Name _PR1: [2]npv!#REF!
Name _PR1: [2]npv!#REF!
Name _PR2: [2]npv!#REF!
Name _PR2: [2]npv!#REF!
Name _PR3: [2]npv!#REF!
Name _PR3: [2]npv!#REF!
Name _PR4: #N/A
Name _Regression_Int: 1
Name \a: #N/A
Name \c: #REF!
Name \c: #REF!
Name \e: #N/A
Name \m: #N/A
Name \p: #N/A
Name \q: #N/A
Name \r: #N/A
Name \w: #N/A
Name \y: #REF!
Name \y: #REF!
Name \z: #REF!
Name \z: #REF!
Name a: #REF!
Name a: #REF!
Name aa: #N/A
Name aaa: #REF!
Name aaa: #REF!
Name AAAA: #REF!
Name AAAA: #REF!
Name AAAAA: #REF!
Name AAAAA: #REF!
Name AAAAAAAAA: [3]일일특이사항!#REF!
Name AAAAAAAAA: [3]일일특이사항!#REF!
Name Access_Button: "업체현황_카드발송_List"
Name Access_Button1: "업체현황_카드발송_List"
Name Access_Button2: "업체현황_카드발송_List"
Name Access_Button3: "카드발송_카드발송_List1"
Name Access_Button4: "업체현황_카드발송_List"
Name AccessDatabase: "C:\생산판매\long98\9802장판원본.mdb"
Name ASDF: OFFSET(#REF!,,[4]!스크롤,1,13)
Name ASDF: OFFSET(#REF!,,[4]!스크롤,1,13)
Name asdfadsfa: #REF!
Name asdfadsfa: #REF!
Name assadad: #REF!
Name assadad: #REF!
Name asss: #REF!

Sheet Total
C2: 작업 | D2: Crane 종류 | E2: 챔버 | F2: 세부 작업 항목 | G2: 일정
AC3: 26년 11월 | BG3: 26년 12월 | CL3: 27년 1월 | DQ3: 27년 2월 | ES3: 27년 3월 | FX3: 27년 4월 | HB3: 27년 5월 | IG3: 27년 6월 | JK3: 27년 7월 | KP3: 27년 8월 | LU3: 27년 9월
G5: 날짜 | H5: 진행률 | I5: 26' 6월 | M5: 26' 7월 | Q5: 26' 8월 | U5: 26' 9월 | Y5: 26' 10월 | AC5: 46327 | AD5: 46328 | AE5: 46329 | AF5: 46330 | AG5: 46331 | AH5: 46332 | AI5: 46333 | AJ5: 46334 | AK5: 46335 | AL5: 46336 | AM5: 46337 | AN5: 46338 | AO5: 46339 | AP5: 46340 | AQ5: 46341 | AR5: 46342 | AS5: 46343 | AT5: 46344 | AU5: 46345 | AV5: 46346 | AW5: 46347 | AX5: 46348 | AY5: 46349 | AZ5: 46350 | BA5: 46351 | BB5: 46352 | BC5: 46353 | BD5: 46354 | BE5: 46355 | BF5: 46356 | BG5: 46357 | BH5: 46358 | BI5: 46359 | BJ5: 46360 | BK5: 46361 | BL5: 46362 | BM5: 46363 | BN5: 46364 | BO5: 46365 | BP5: 46366 | BQ5: 46367 | BR5: 46368 | BS5: 46369 | BT5: 46370 | BU5: 46371 | BV5: 46372 | BW5: 46373 | BX5: 46374 | BY5: 46375 | BZ5: 46376 | CA5: 46377 | CB5: 46378 | CC5: 46379 | CD5: 46380 | CE5: 46381 | CF5: 46382 | CG5: 46383 | CH5: 46384 | CI5: 46385 | CJ5: 46386 | CK5: 46387 | CL5: 46388 | CM5: 46389 | CN5: 46390 | CO5: 46391 | CP5: 46392 | CQ5: 46393 | CR5: 46394 | CS5: 46395 | CT5: 46396 | CU5: 46397 | CV5: 46398 | CW5: 46399 | CX5: 46400 | CY5: 46401 | CZ5: 46402 | DA5: 46403 | DB5: 46404 | DC5: 46405 | DD5: 46406 | DE5: 46407 | DF5: 46408 | DG5: 46409 | DH5: 46410 | DI5: 46411 | DJ5: 46412 | DK5: 46413 | DL5: 46414 | DM5: 46415 | DN5: 46416 | DO5: 46417 | DP5: 46418 | DQ5: 46419 | DR5: 46420 | DS5: 46421 | DT5: 46422 | DU5: 46423 | DV5: 46424 | DW5: 46425 | DX5: 46426 | DY5: 46427 | DZ5: 46428 | EA5: 46429 | EB5: 46430 | EC5: 46431 | ED5: 46432 | EE5: 46433 | EF5: 46434 | EG5: 46435 | EH5: 46436 | EI5: 46437 | EJ5: 46438 | EK5: 46439 | EL5: 46440 | EM5: 46441 | EN5: 46442 | EO5: 46443 | EP5: 46444 | EQ5: 46445 | ER5: 46446 | ES5: 46447 | ET5: 46448 | EU5: 46449 | EV5: 46450 | EW5: 46451 | EX5: 46452 | EY5: 46453 | EZ5: 46454 | FA5: 46455 | FB5: 46456 | FC5: 46457 | FD5: 46458 | FE5: 46459 | FF5: 46460 | FG5: 46461 | FH5: 46462 | FI5: 46463 | FJ5: 46464 | FK5: 46465 | FL5: 46466 | FM5: 46467 | FN5: 46468 | FO5: 46469 | FP5: 46470 | FQ5: 46471 | FR5: 46472 | FS5: 46473 | FT5: 46474 | FU5: 46475 | FV5: 46476 | FW5: 46477 | FX5: 46478 | FY5: 46479 | FZ5: 46480 | GA5: 46481 | GB5: 46482 | GC5: 46483 | GD5: 46484 | GE5: 46485 | GF5: 46486 | GG5: 46487 | GH5: 46488 | GI5: 46489 | GJ5: 46490 | GK5: 46491 | GL5: 46492 | GM5: 46493 | GN5: 46494 | GO5: 46495 | GP5: 46496 | GQ5: 46497 | GR5: 46498 | GS5: 46499 | GT5: 46500 | GU5: 46501 | GV5: 46502 | GW5: 46503 | GX5: 46504 | GY5: 46505 | GZ5: 46506 | HA5: 46507 | HB5: 46508 | HC5: 46509 | HD5: 46510 | HE5: 46511 | HF5: 46512 | HG5: 46513 | HH5: 46514 | HI5: 46515 | HJ5: 46516 | HK5: 46517 | HL5: 46518 | HM5: 46519 | HN5: 46520 | HO5: 46521 | HP5: 46522 | HQ5: 46523 | HR5: 46524 | HS5: 46525 | HT5: 46526 | HU5: 46527 | HV5: 46528 | HW5: 46529 | HX5: 46530 | HY5: 46531 | HZ5: 46532 | IA5: 46533 | IB5: 46534 | IC5: 46535 | ID5: 46536 | IE5: 46537 | IF5: 46538 | IG5: 46539 | IH5: 46540 | II5: 46541 | IJ5: 46542 | IK5: 46543 | IL5: 46544 | IM5: 46545 | IN5: 46546 | IO5: 46547 | IP5: 46548 | IQ5: 46549 | IR5: 46550 | IS5: 46551 | IT5: 46552 | IU5: 46553 | IV5: 46554 | IW5: 46555 | IX5: 46556 | IY5: 46557 | IZ5: 46558 | JA5: 46559 | JB5: 46560 | JC5: 46561 | JD5: 46562 | JE5: 46563 | JF5: 46564 | JG5: 46565 | JH5: 46566 | JI5: 46567 | JJ5: 46568 | JK5: 46569 | JL5: 46570 | JM5: 46571 | JN5: 46572 | JO5: 46573 | JP5: 46574 | JQ5: 46575 | JR5: 46576 | JS5: 46577 | JT5: 46578 | JU5: 46579 | JV5: 46580 | JW5: 46581 | JX5: 46582 | JY5: 46583 | JZ5: 46584 | KA5: 46585 | KB5: 46586 | KC5: 46587 | KD5: 46588 | KE5: 46589 | KF5: 46590 | KG5: 46591 | KH5: 46592 | KI5: 46593 | KJ5: 46594 | KK5: 46595 | KL5: 46596 | KM5: 46597 | KN5: 46598 | KO5: 46599 | KP5: 46600 | KQ5: 46601 | KR5: 46602 | KS5: 46603 | KT5: 46604 | KU5: 46605 | KV5: 46606 | KW5: 46607 | KX5: 46608 | KY5: 46609 | KZ5: 46610 | LA5: 46611 | LB5: 46612 | LC5: 46613 | LD5: 46614 | LE5: 46615 | LF5: 46616 | LG5: 46617 | LH5: 46618 | LI5: 46619 | LJ5: 46620 | LK5: 46621 | LL5: 46622 | LM5: 46623 | LN5: 46624 | LO5: 46625 | LP5: 46626 | LQ5: 46627 | LR5: 46628 | LS5: 46629 | LT5: 46630 | LU5: 46631 | LV5: 46632 | LW5: 46633 | LX5: 46634 | LY5: 46635 | LZ5: 46636 | MA5: 46637 | MB5: 46638 | MC5: 46639 | MD5: 46640 | ME5: 46641
G6: 요일 | I6: 1주 | J6: 2주 | K6: 3주 | L6: 4주 | M6: 1주 | N6: 2주 | O6: 3주 | P6: 4주 | Q6: 1주 | R6: 2주 | S6: 3주 | T6: 4주 | U6: 1주 | V6: 2주 | W6: 3주 | X6: 4주 | Y6: 1주 | Z6: 2주 | AA6: 3주 | AB6: 4주 | AC6: 일 | AD6: 월 | AE6: 화 | AF6: 수 | AG6: 목 | AH6: 금 | AI6: 토 | AJ6: 일 | AK6: 월 | AL6: 화 | AM6: 수 | AN6: 목 | AO6: 금 | AP6: 토 | AQ6: 일 | AR6: 월 | AS6: 화 | AT6: 수 | AU6: 목 | AV6: 금 | AW6: 토 | AX6: 일 | AY6: 월 | AZ6: 화 | BA6: 수 | BB6: 목 | BC6: 금 | BD6: 토 | BE6: 일 | BF6: 월 | BG6: 화 | BH6: 수 | BI6: 목 | BJ6: 금 | BK6: 토 | BL6: 일 | BM6: 월 | BN6: 화 | BO6: 수 | BP6: 목 | BQ6: 금 | BR6: 토 | BS6: 일 | BT6: 월 | BU6: 화 | BV6: 수 | BW6: 목 | BX6: 금 | BY6: 토 | BZ6: 일 | CA6: 월 | CB6: 화 | CC6: 수 | CD6: 목 | CE6: 금 | CF6: 토 | CG6: 일 | CH6: 월 | CI6: 화 | CJ6: 수 | CK6: 목 | CL6: 금 | CM6: 토 | CN6: 일 | CO6: 월 | CP6: 화 | CQ6: 수 | CR6: 목 | CS6: 금 | CT6: 토 | CU6: 일 | CV6: 월 | CW6: 화 | CX6: 수 | CY6: 목 | CZ6: 금 | DA6: 토 | DB6: 일 | DC6: 월 | DD6: 화 | DE6: 수 | DF6: 목 | DG6: 금 | DH6: 토 | DI6: 일 | DJ6: 월 | DK6: 화 | DL6: 수 | DM6: 목 | DN6: 금 | DO6: 토 | DP6: 일 | DQ6: 월 | DR6: 화 | DS6: 수 | DT6: 목 | DU6: 금 | DV6: 토 | DW6: 일 | DX6: 월 | DY6: 화 | DZ6: 수 | EA6: 목 | EB6: 금 | EC6: 토 | ED6: 일 | EE6: 월 | EF6: 화 | EG6: 수 | EH6: 목 | EI6: 금 | EJ6: 토 | EK6: 일 | EL6: 월 | EM6: 화 | EN6: 수 | EO6: 목 | EP6: 금 | EQ6: 토 | ER6: 일 | ES6: 월 | ET6: 화 | EU6: 수 | EV6: 목 | EW6: 금 | EX6: 토 | EY6: 일 | EZ6: 월 | FA6: 화 | FB6: 수 | FC6: 목 | FD6: 금 | FE6: 토 | FF6: 일 | FG6: 월 | FH6: 화 | FI6: 수 | FJ6: 목 | FK6: 금 | FL6: 토 | FM6: 일 | FN6: 월 | FO6: 화 | FP6: 수 | FQ6: 목 | FR6: 금 | FS6: 토 | FT6: 일 | FU6: 월 | FV6: 화 | FW6: 수 | FX6: 목 | FY6: 금 | FZ6: 토 | GA6: 일 | GB6: 월 | GC6: 화 | GD6: 수 | GE6: 목 | GF6: 금 | GG6: 토 | GH6: 일 | GI6: 월 | GJ6: 화 | GK6: 수 | GL6: 목 | GM6: 금 | GN6: 토 | GO6: 일 | GP6: 월 | GQ6: 화 | GR6: 수 | GS6: 목 | GT6: 금 | GU6: 토 | GV6: 일 | GW6: 월 | GX6: 화 | GY6: 수 | GZ6: 목 | HA6: 금 | HB6: 토 | HC6: 일 | HD6: 월 | HE6: 화 | HF6: 수 | HG6: 목 | HH6: 금 | HI6: 토 | HJ6: 일 | HK6: 월 | HL6: 화 | HM6: 수 | HN6: 목 | HO6: 금 | HP6: 토 | HQ6: 일 | HR6: 월 | HS6: 화 | HT6: 수 | HU6: 목 | HV6: 금 | HW6: 토 | HX6: 일 | HY6: 월 | HZ6: 화 | IA6: 수 | IB6: 목 | IC6: 금 | ID6: 토 | IE6: 일 | IF6: 월 | IG6: 화 | IH6: 수 | II6: 목 | IJ6: 금 | IK6: 토 | IL6: 일 | IM6: 월 | IN6: 화 | IO6: 수 | IP6: 목 | IQ6: 금 | IR6: 토 | IS6: 일 | IT6: 월 | IU6: 화 | IV6: 수 | IW6: 목 | IX6: 금 | IY6: 토 | IZ6: 일 | JA6: 월 | JB6: 화 | JC6: 수 | JD6: 목 | JE6: 금 | JF6: 토 | JG6: 일 | JH6: 월 | JI6: 화 | JJ6: 수 | JK6: 목 | JL6: 금 | JM6: 토 | JN6: 일 | JO6: 월 | JP6: 화 | JQ6: 수 | JR6: 목 | JS6: 금 | JT6: 토 | JU6: 일 | JV6: 월 | JW6: 화 | JX6: 수 | JY6: 목 | JZ6: 금 | KA6: 토 | KB6: 일 | KC6: 월 | KD6: 화 | KE6: 수 | KF6: 목 | KG6: 금 | KH6: 토 | KI6: 일 | KJ6: 월 | KK6: 화 | KL6: 수 | KM6: 목 | KN6: 금 | KO6: 토 | KP6: 일 | KQ6: 월 | KR6: 화 | KS6: 수 | KT6: 목 | KU6: 금 | KV6: 토 | KW6: 일 | KX6: 월 | KY6: 화 | KZ6: 수 | LA6: 목 | LB6: 금 | LC6: 토 | LD6: 일 | LE6: 월 | LF6: 화 | LG6: 수 | LH6: 목 | LI6: 금 | LJ6: 토 | LK6: 일 | LL6: 월 | LM6: 화 | LN6: 수 | LO6: 목 | LP6: 금 | LQ6: 토 | LR6: 일 | LS6: 월 | LT6: 화 | LU6: 수 | LV6: 목 | LW6: 금 | LX6: 토 | LY6: 일 | LZ6: 월 | MA6: 화 | MB6: 수 | MC6: 목 | MD6: 금 | ME6: 토
C7: 전장 작업 | F7: Local parts & Sensor cable 포설 | G7: 계획 | H7: 0 | I7: 0 | J7: 0 | K7: 0 | L7: 0 | M7: 0 | N7: 0 | O7: 0 | P7: 0 | Q7: 0 | R7: 0 | S7: 0 | T7: 0 | U7: 0 | V7: 0 | W7: 0 | X7: 0 | Y7: 0 | Z7: 0 | AA7: 0 | AB7: 0 | AC7: 0 | AD7: 0 | AE7: 0 | AF7: 0 | AG7: 0 | AH7: 0 | AI7: 0 | AJ7: 0 | AK7: 0 | AL7: 0 | AM7: 0 | AN7: 0 | AO7: 0 | AP7: 0 | AQ7: 0 | AR7: 0 | AS7: 0 | AT7: 0 | AU7: 0 | AV7: 0 | AW7: 0 | AX7: 0 | AY7: 0 | AZ7: 0 | BA7: 0 | BB7: 0 | BC7: 0 | BD7: 0 | BE7: 0 | BF7: 0 | BG7: 0 | BH7: 0 | BI7: 0 | BJ7: 2 | BK7: 2 | BL7: 0 | BM7: 0 | BN7: 0 | BO7: 0 | BP7: 0 | BQ7: 0 | BR7: 0 | BS7: 0 | BT7: 0 | BU7: 0 | BV7: 0 | BW7: 0 | BX7: 0 | BY7: 0 | BZ7: 0 | CA7: 0 | CB7: 0 | CC7: 0 | CD7: 0 | CE7: 0 | CF7: 0 | CG7: 0 | CH7: 0 | CI7: 0 | CJ7: 0 | CK7: 0 | CL7: 0 | CM7: 0 | CN7: 0 | CO7: 0 | CP7: 0 | CQ7: 0 | CR7: 0 | CS7: 0 | CT7: 0 | CU7: 0 | CV7: 0 | CW7: 0 | CX7: 0 | CY7: 0 | CZ7: 0 | DA7: 0 | DB7: 0 | DC7: 0 | DD7: 0 | DE7: 0 | DF7: 0 | DG7: 0 | DH7: 0 | DI7: 0 | DJ7: 0 | DK7: 0 | DL7: 0 | DM7: 0 | DN7: 0 | DO7: 0 | DP7: 0 | DQ7: 0 | DR7: 0 | DS7: 0 | DT7: 0 | DU7: 0 | DV7: 0 | DW7: 0 | DX7: 0 | DY7: 0 | DZ7: 0 | EA7: 0 | EB7: 0 | EC7: 0 | ED7: 0 | EE7: 0 | EF7: 0 | EG7: 0 | EH7: 0 | EI7: 0 | EJ7: 0 | EK7: 0 | EL7: 0 | EM7: 0 | EN7: 0 | EO7: 0 | EP7: 0 | EQ7: 0 | ER7: 0 | ES7: 0 | ET7: 0 | EU7: 0 | EV7: 0 | EW7: 0 | EX7: 0 | EY7: 0 | EZ7: 0 | FA7: 0 | FB7: 0 | FC7: 0 | FD7: 0 | FE7: 0 | FF7: 0 | FG7: 0 | FH7: 0 | FI7: 0 | FJ7: 0 | FK7: 0 | FL7: 0 | FM7: 0 | FN7: 0 | FO7: 0 | FP7: 0 | FQ7: 0 | FR7: 0 | FS7: 0 | FT7: 0 | FU7: 0 | FV7: 0 | FW7: 0 | FX7: 0 | FY7: 0 | FZ7: 0 | GA7: 0 | GB7: 0 | GC7: 0 | GD7: 0 | GE7: 0 | GF7: 0 | GG7: 0 | GH7: 0 | GI7: 0 | GJ7: 0 | GK7: 0 | GL7: 0 | GM7: 0 | GN7: 0 | GO7: 0 | GP7: 0 | GQ7: 0 | GR7: 0 | GS7: 0 | GT7: 0 | GU7: 0 | GV7: 0 | GW7: 0 | GX7: 0 | GY7: 0 | GZ7: 0 | HA7: 0 | HB7: 0 | HC7: 0 | HD7: 0 | HE7: 0 | HF7: 0 | HG7: 0 | HH7: 0 | HI7: 0 | HJ7: 0 | HK7: 0 | HL7: 0 | HM7: 0 | HN7: 0 | HO7: 0 | HP7: 0 | HQ7: 0 | HR7: 0 | HS7: 0 | HT7: 0 | HU7: 0 | HV7: 0 | HW7: 0 | HX7: 0 | HY7: 0 | HZ7: 0 | IA7: 0 | IB7: 0 | IC7: 0 | ID7: 0 | IE7: 0 | IF7: 0 | IG7: 0 | IH7: 0 | II7: 0 | IJ7: 0 | IK7: 0 | IL7: 0 | IM7: 0 | IN7: 0 | IO7: 0 | IP7: 0 | IQ7: 0 | IR7: 0 | IS7: 0 | IT7: 0 | IU7: 0 | IV7: 0 | IW7: 0 | IX7: 0 | IY7: 0 | IZ7: 0 | JA7: 0 | JB7: 0 | JC7: 0 | JD7: 0 | JE7: 0 | JF7: 0 | JG7: 0 | JH7: 0 | JI7: 0 | JJ7: 0 | JK7: 0 | JL7: 0 | JM7: 0 | JN7: 0 | JO7: 0 | JP7: 0 | JQ7: 0 | JR7: 0 | JS7: 0 | JT7: 0 | JU7: 0 | JV7: 0 | JW7: 0 | JX7: 0 | JY7: 0 | JZ7: 0 | KA7: 0 | KB7: 0 | KC7: 0 | KD7: 0 | KE7: 0 | KF7: 0 | KG7: 0 | KH7: 0 | KI7: 0 | KJ7: 0 | KK7: 0 | KL7: 0 | KM7: 0 | KN7: 0 | KO7: 0 | KP7: 0 | KQ7: 0 | KR7: 0 | KS7: 0 | KT7: 0 | KU7: 0 | KV7: 0 | KW7: 0 | KX7: 0 | KY7: 0 | KZ7: 0 | LA7: 0 | LB7: 0 | LC7: 0 | LD7: 0 | LE7: 0 | LF7: 0 | LG7: 0 | LH7: 0 | LI7: 0 | LJ7: 0 | LK7: 0 | LL7: 0 | LM7: 0 | LN7: 0 | LO7: 0 | LP7: 0 | LQ7: 0 | LR7: 0 | LS7: 0 | LT7: 0 | LU7: 0 | LV7: 0 | LW7: 0 | LX7: 0 | LY7: 0 | LZ7: 0 | MA7: 0 | MB7: 0 | MC7: 0 | MD7: 0 | ME7: 0
G8: 실행
F9: Rack & ATM Box 내부 cable 포설 PM#1 (UVW /Review/ESC) | G9: 계획 | H9: 0 | I9: 0 | J9: 0 | K9: 0 | L9: 0 | M9: 0 | N9: 0 | O9: 0 | P9: 0 | Q9: 0 | R9: 0 | S9: 0 | T9: 0 | U9: 0 | V9: 0 | W9: 0 | X9: 0 | Y9: 0 | Z9: 0 | AA9: 0 | AB9: 0 | AC9: 0 | AD9: 1 | AE9: 1 | AF9: 1 | AG9: 0 | AH9: 0 | AI9: 0 | AJ9: 0 | AK9: 0 | AL9: 0 | AM9: 0 | AN9: 0 | AO9: 0 | AP9: 0 | AQ9: 0 | AR9: 0 | AS9: 0 | AT9: 0 | AU9: 0 | AV9: 0 | AW9: 0 | AX9: 0 | AY9: 0 | AZ9: 0 | BA9: 0 | BB9: 0 | BC9: 0 | BD9: 0 | BE9: 0 | BF9: 0 | BG9: 0 | BH9: 0 | BI9: 0 | BJ9: 0 | BK9: 0 | BL9: 0 | BM9: 2 | BN9: 2 | BO9: 2 | BP9: 2 | BQ9: 2 | BR9: 0 | BS9: 0 | BT9: 0 | BU9: 0 | BV9: 0 | BW9: 0 | BX9: 0 | BY9: 0 | BZ9: 0 | CA9: 0 | CB9: 0 | CC9: 0 | CD9: 0 | CE9: 0 | CF9: 0 | CG9: 0 | CH9: 0 | CI9: 0 | CJ9: 0 | CK9: 0 | CL9: 0 | CM9: 0 | CN9: 0 | CO9: 0 | CP9: 0 | CQ9: 0 | CR9: 0 | CS9: 0 | CT9: 0 | CU9: 0 | CV9: 0 | CW9: 0 | CX9: 0 | CY9: 0 | CZ9: 0 | DA9: 0 | DB9: 0 | DC9: 0 | DD9: 0 | DE9: 0 | DF9: 0 | DG9: 0 | DH9: 0 | DI9: 0 | DJ9: 0 | DK9: 0 | DL9: 0 | DM9: 0 | DN9: 0 | DO9: 0 | DP9: 0 | DQ9: 0 | DR9: 0 | DS9: 0 | DT9: 0 | DU9: 0 | DV9: 0 | DW9: 0 | DX9: 0 | DY9: 0 | DZ9: 0 | EA9: 0 | EB9: 0 | EC9: 0 | ED9: 0 | EE9: 0 | EF9: 0 | EG9: 0 | EH9: 0 | EI9: 0 | EJ9: 0 | EK9: 0 | EL9: 0 | EM9: 0 | EN9: 0 | EO9: 0 | EP9: 0 | EQ9: 0 | ER9: 0 | ES9: 0 | ET9: 0 | EU9: 0 | EV9: 0 | EW9: 0 | EX9: 0 | EY9: 0 | EZ9: 0 | FA9: 0 | FB9: 0 | FC9: 0 | FD9: 0 | FE9: 0 | FF9: 0 | FG9: 0 | FH9: 0 | FI9: 0 | FJ9: 0 | FK9: 0 | FL9: 0 | FM9: 0 | FN9: 0 | FO9: 0 | FP9: 0 | FQ9: 0 | FR9: 0 | FS9: 0 | FT9: 0 | FU9: 0 | FV9: 0 | FW9: 0 | FX9: 0 | FY9: 0 | FZ9: 0 | GA9: 0 | GB9: 0 | GC9: 0 | GD9: 0 | GE9: 0 | GF9: 0 | GG9: 0 | GH9: 0 | GI9: 0 | GJ9: 0 | GK9: 0 | GL9: 0 | GM9: 0 | GN9: 0 | GO9: 0 | GP9: 0 | GQ9: 0 | GR9: 0 | GS9: 0 | GT9: 0 | GU9: 0 | GV9: 0 | GW9: 0 | GX9: 0 | GY9: 0 | GZ9: 0 | HA9: 0 | HB9: 0 | HC9: 0 | HD9: 0 | HE9: 0 | HF9: 0 | HG9: 0 | HH9: 0 | HI9: 0 | HJ9: 0 | HK9: 0 | HL9: 0 | HM9: 0 | HN9: 0 | HO9: 0 | HP9: 0 | HQ9: 0 | HR9: 0 | HS9: 0 | HT9: 0 | HU9: 0 | HV9: 0 | HW9: 0 | HX9: 0 | HY9: 0 | HZ9: 0 | IA9: 0 | IB9: 0 | IC9: 0 | ID9: 0 | IE9: 0 | IF9: 0 | IG9: 0 | IH9: 0 | II9: 0 | IJ9: 0 | IK9: 0 | IL9: 0 | IM9: 0 | IN9: 0 | IO9: 0 | IP9: 0 | IQ9: 0 | IR9: 0 | IS9: 0 | IT9: 0 | IU9: 0 | IV9: 0 | IW9: 0 | IX9: 0 | IY9: 0 | IZ9: 0 | JA9: 0 | JB9: 0 | JC9: 0 | JD9: 0 | JE9: 0 | JF9: 0 | JG9: 0 | JH9: 0 | JI9: 0 | JJ9: 0 | JK9: 0 | JL9: 0 | JM9: 0 | JN9: 0 | JO9: 0 | JP9: 0 | JQ9: 0 | JR9: 0 | JS9: 0 | JT9: 0 | JU9: 0 | JV9: 0 | JW9: 0 | JX9: 0 | JY9: 0 | JZ9: 0 | KA9: 0 | KB9: 0 | KC9: 0 | KD9: 0 | KE9: 0 | KF9: 0 | KG9: 0 | KH9: 0 | KI9: 0 | KJ9: 0 | KK9: 0 | KL9: 0 | KM9: 0 | KN9: 0 | KO9: 0 | KP9: 0 | KQ9: 0 | KR9: 0 | KS9: 0 | KT9: 0 | KU9: 0 | KV9: 0 | KW9: 0 | KX9: 0 | KY9: 0 | KZ9: 0 | LA9: 0 | LB9: 0 | LC9: 0 | LD9: 0 | LE9: 0 | LF9: 0 | LG9: 0 | LH9: 0 | LI9: 0 | LJ9: 0 | LK9: 0 | LL9: 0 | LM9: 0 | LN9: 0 | LO9: 0 | LP9: 0 | LQ9: 0 | LR9: 0 | LS9: 0 | LT9: 0 | LU9: 0 | LV9: 0 | LW9: 0 | LX9: 0 | LY9: 0 | LZ9: 0 | MA9: 0 | MB9: 0 | MC9: 0 | MD9: 0 | ME9: 0
G10: 실행
F11: 챔버 내부 Gore cable 포설 | G11: 계획 | H11: 0 | I11: 0 | J11: 0 | K11: 0 | L11: 0 | M11: 0 | N11: 0 | O11: 0 | P11: 0 | Q11: 0 | R11: 0 | S11: 0 | T11: 0 | U11: 0 | V11: 0 | W11: 0 | X11: 0 | Y11: 0 | Z11: 0 | AA11: 0 | AB11: 0 | AC11: 0 | AD11: 0 | AE11: 0 | AF11: 0 | AG11: 1 | AH11: 1 | AI11: 1 | AJ11: 0 | AK11: 0 | AL11: 0 | AM11: 0 | AN11: 0 | AO11: 0 | AP11: 0 | AQ11: 0 | AR11: 0 | AS11: 0 | AT11: 0 | AU11: 0 | AV11: 0 | AW11: 0 | AX11: 0 | AY11: 0 | AZ11: 0 | BA11: 0 | BB11: 0 | BC11: 0 | BD11: 0 | BE11: 0 | BF11: 0 | BG11: 0 | BH11: 0 | BI11: 0 | BJ11: 0 | BK11: 0 | BL11: 0 | BM11: 0 | BN11: 0 | BO11: 0 | BP11: 0 | BQ11: 0 | BR11: 2 | BS11: 0 | BT11: 2 | BU11: 0 | BV11: 0 | BW11: 0 | BX11: 0 | BY11: 0 | BZ11: 0 | CA11: 0 | CB11: 0 | CC11: 0 | CD11: 0 | CE11: 0 | CF11: 0 | CG11: 0 | CH11: 0 | CI11: 0 | CJ11: 0 | CK11: 0 | CL11: 0 | CM11: 0 | CN11: 0 | CO11: 0 | CP11: 0 | CQ11: 0 | CR11: 0 | CS11: 0 | CT11: 0 | CU11: 0 | CV11: 0 | CW11: 0 | CX11: 0 | CY11: 0 | CZ11: 0 | DA11: 0 | DB11: 0 | DC11: 0 | DD11: 0 | DE11: 0 | DF11: 0 | DG11: 0 | DH11: 0 | DI11: 0 | DJ11: 0 | DK11: 0 | DL11: 0 | DM11: 0 | DN11: 0 | DO11: 0 | DP11: 0 | DQ11: 0 | DR11: 0 | DS11: 0 | DT11: 0 | DU11: 0 | DV11: 0 | DW11: 0 | DX11: 0 | DY11: 0 | DZ11: 0 | EA11: 0 | EB11: 0 | EC11: 0 | ED11: 0 | EE11: 0 | EF11: 0 | EG11: 0 | EH11: 0 | EI11: 0 | EJ11: 0 | EK11: 0 | EL11: 0 | EM11: 0 | EN11: 0 | EO11: 0 | EP11: 0 | EQ11: 0 | ER11: 0 | ES11: 0 | ET11: 0 | EU11: 0 | EV11: 0 | EW11: 0 | EX11: 0 | EY11: 0 | EZ11: 0 | FA11: 0 | FB11: 0 | FC11: 0 | FD11: 0 | FE11: 0 | FF11: 0 | FG11: 0 | FH11: 0 | FI11: 0 | FJ11: 0 | FK11: 0 | FL11: 0 | FM11: 0 | FN11: 0 | FO11: 0 | FP11: 0 | FQ11: 0 | FR11: 0 | FS11: 0 | FT11: 0 | FU11: 0 | FV11: 0 | FW11: 0 | FX11: 0 | FY11: 0 | FZ11: 0 | GA11: 0 | GB11: 0 | GC11: 0 | GD11: 0 | GE11: 0 | GF11: 0 | GG11: 0 | GH11: 0 | GI11: 0 | GJ11: 0 | GK11: 0 | GL11: 0 | GM11: 0 | GN11: 0 | GO11: 0 | GP11: 0 | GQ11: 0 | GR11: 0 | GS11: 0 | GT11: 0 | GU11: 0 | GV11: 0 | GW11: 0 | GX11: 0 | GY11: 0 | GZ11: 0 | HA11: 0 | HB11: 0 | HC11: 0 | HD11: 0 | HE11: 0 | HF11: 0 | HG11: 0 | HH11: 0 | HI11: 0 | HJ11: 0 | HK11: 0 | HL11: 0 | HM11: 0 | HN11: 0 | HO11: 0 | HP11: 0 | HQ11: 0 | HR11: 0 | HS11: 0 | HT11: 0 | HU11: 0 | HV11: 0 | HW11: 0 | HX11: 0 | HY11: 0 | HZ11: 0 | IA11: 0 | IB11: 0 | IC11: 0 | ID11: 0 | IE11: 0 | IF11: 0 | IG11: 0 | IH11: 0 | II11: 0 | IJ11: 0 | IK11: 0 | IL11: 0 | IM11: 0 | IN11: 0 | IO11: 0 | IP11: 0 | IQ11: 0 | IR11: 0 | IS11: 0 | IT11: 0 | IU11: 0 | IV11: 0 | IW11: 0 | IX11: 0 | IY11: 0 | IZ11: 0 | JA11: 0 | JB11: 0 | JC11: 0 | JD11: 0 | JE11: 0 | JF11: 0 | JG11: 0 | JH11: 0 | JI11: 0 | JJ11: 0 | JK11: 0 | JL11: 0 | JM11: 0 | JN11: 0 | JO11: 0 | JP11: 0 | JQ11: 0 | JR11: 0 | JS11: 0 | JT11: 0 | JU11: 0 | JV11: 0 | JW11: 0 | JX11: 0 | JY11: 0 | JZ11: 0 | KA11: 0 | KB11: 0 | KC11: 0 | KD11: 0 | KE11: 0 | KF11: 0 | KG11: 0 | KH11: 0 | KI11: 0 | KJ11: 0 | KK11: 0 | KL11: 0 | KM11: 0 | KN11: 0 | KO11: 0 | KP11: 0 | KQ11: 0 | KR11: 0 | KS11: 0 | KT11: 0 | KU11: 0 | KV11: 0 | KW11: 0 | KX11: 0 | KY11: 0 | KZ11: 0 | LA11: 0 | LB11: 0 | LC11: 0 | LD11: 0 | LE11: 0 | LF11: 0 | LG11: 0 | LH11: 0 | LI11: 0 | LJ11: 0 | LK11: 0 | LL11: 0 | LM11: 0 | LN11: 0 | LO11: 0 | LP11: 0 | LQ11: 0 | LR11: 0 | LS11: 0 | LT11: 0 | LU11: 0 | LV11: 0 | LW11: 0 | LX11: 0 | LY11: 0 | LZ11: 0 | MA11: 0 | MB11: 0 | MC11: 0 | MD11: 0 | ME11: 0
G12: 실행
F13: Ex 챔버 cable 포설 | G13: 계획 | H13: 0 | I13: 0 | J13: 0 | K13: 0 | L13: 0 | M13: 0 | N13: 0 | O13: 0 | P13: 0 | Q13: 0 | R13: 0 | S13: 0 | T13: 0 | U13: 0 | V13: 0 | W13: 0 | X13: 0 | Y13: 0 | Z13: 0 | AA13: 0 | AB13: 0 | AC13: 0 | AD13: 0 | AE13: 0 | AF13: 0 | AG13: 0 | AH13: 0 | AI13: 0 | AJ13: 0 | AK13: 1 | AL13: 0 | AM13: 0 | AN13: 0 | AO13: 0 | AP13: 0 | AQ13: 0 | AR13: 0 | AS13: 0 | AT13: 0 | AU13: 0 | AV13: 0 | AW13: 0 | AX13: 0 | AY13: 0 | AZ13: 0 | BA13: 0 | BB13: 0 | BC13: 0 | BD13: 0 | BE13: 0 | BF13: 0 | BG13: 0 | BH13: 0 | BI13: 0 | BJ13: 0 | BK13: 0 | BL13: 0 | BM13: 0 | BN13: 0 | BO13: 0 | BP13: 0 | BQ13: 0 | BR13: 0 | BS13: 0 | BT13: 0 | BU13: 0 | BV13: 2 | BW13: 0 | BX13: 0 | BY13: 0 | BZ13: 0 | CA13: 0 | CB13: 0 | CC13: 0 | CD13: 0 | CE13: 0 | CF13: 0 | CG13: 0 | CH13: 0 | CI13: 0 | CJ13: 0 | CK13: 0 | CL13: 0 | CM13: 0 | CN13: 0 | CO13: 0 | CP13: 0 | CQ13: 0 | CR13: 0 | CS13: 0 | CT13: 0 | CU13: 0 | CV13: 0 | CW13: 0 | CX13: 0 | CY13: 0 | CZ13: 0 | DA13: 0 | DB13: 0 | DC13: 0 | DD13: 0 | DE13: 0 | DF13: 0 | DG13: 0 | DH13: 0 | DI13: 0 | DJ13: 0 | DK13: 0 | DL13: 0 | DM13: 0 | DN13: 0 | DO13: 0 | DP13: 0 | DQ13: 0 | DR13: 0 | DS13: 0 | DT13: 0 | DU13: 0 | DV13: 0 | DW13: 0 | DX13: 0 | DY13: 0 | DZ13: 0 | EA13: 0 | EB13: 0 | EC13: 0 | ED13: 0 | EE13: 0 | EF13: 0 | EG13: 0 | EH13: 0 | EI13: 0 | EJ13: 0 | EK13: 0 | EL13: 0 | EM13: 0 | EN13: 0 | EO13: 0 | EP13: 0 | EQ13: 0 | ER13: 0 | ES13: 0 | ET13: 0 | EU13: 0 | EV13: 0 | EW13: 0 | EX13: 0 | EY13: 0 | EZ13: 0 | FA13: 0 | FB13: 0 | FC13: 0 | FD13: 0 | FE13: 0 | FF13: 0 | FG13: 0 | FH13: 0 | FI13: 0 | FJ13: 0 | FK13: 0 | FL13: 0 | FM13: 0 | FN13: 0 | FO13: 0 | FP13: 0 | FQ13: 0 | FR13: 0 | FS13: 0 | FT13: 0 | FU13: 0 | FV13: 0 | FW13: 0 | FX13: 0 | FY13: 0 | FZ13: 0 | GA13: 0 | GB13: 0 | GC13: 0 | GD13: 0 | GE13: 0 | GF13: 0 | GG13: 0 | GH13: 0 | GI13: 0 | GJ13: 0 | GK13: 0 | GL13: 0 | GM13: 0 | GN13: 0 | GO13: 0 | GP13: 0 | GQ13: 0 | GR13: 0 | GS13: 0 | GT13: 0 | GU13: 0 | GV13: 0 | GW13: 0 | GX13: 0 | GY13: 0 | GZ13: 0 | HA13: 0 | HB13: 0 | HC13: 0 | HD13: 0 | HE13: 0 | HF13: 0 | HG13: 0 | HH13: 0 | HI13: 0 | HJ13: 0 | HK13: 0 | HL13: 0 | HM13: 0 | HN13: 0 | HO13: 0 | HP13: 0 | HQ13: 0 | HR13: 0 | HS13: 0 | HT13: 0 | HU13: 0 | HV13: 0 | HW13: 0 | HX13: 0 | HY13: 0 | HZ13: 0 | IA13: 0 | IB13: 0 | IC13: 0 | ID13: 0 | IE13: 0 | IF13: 0 | IG13: 0 | IH13: 0 | II13: 0 | IJ13: 0 | IK13: 0 | IL13: 0 | IM13: 0 | IN13: 0 | IO13: 0 | IP13: 0 | IQ13: 0 | IR13: 0 | IS13: 0 | IT13: 0 | IU13: 0 | IV13: 0 | IW13: 0 | IX13: 0 | IY13: 0 | IZ13: 0 | JA13: 0 | JB13: 0 | JC13: 0 | JD13: 0 | JE13: 0 | JF13: 0 | JG13: 0 | JH13: 0 | JI13: 0 | JJ13: 0 | JK13: 0 | JL13: 0 | JM13: 0 | JN13: 0 | JO13: 0 | JP13: 0 | JQ13: 0 | JR13: 0 | JS13: 0 | JT13: 0 | JU13: 0 | JV13: 0 | JW13: 0 | JX13: 0 | JY13: 0 | JZ13: 0 | KA13: 0 | KB13: 0 | KC13: 0 | KD13: 0 | KE13: 0 | KF13: 0 | KG13: 0 | KH13: 0 | KI13: 0 | KJ13: 0 | KK13: 0 | KL13: 0 | KM13: 0 | KN13: 0 | KO13: 0 | KP13: 0 | KQ13: 0 | KR13: 0 | KS13: 0 | KT13: 0 | KU13: 0 | KV13: 0 | KW13: 0 | KX13: 0 | KY13: 0 | KZ13: 0 | LA13: 0 | LB13: 0 | LC13: 0 | LD13: 0 | LE13: 0 | LF13: 0 | LG13: 0 | LH13: 0 | LI13: 0 | LJ13: 0 | LK13: 0 | LL13: 0 | LM13: 0 | LN13: 0 | LO13: 0 | LP13: 0 | LQ13: 0 | LR13: 0 | LS13: 0 | LT13: 0 | LU13: 0 | LV13: 0 | LW13: 0 | LX13: 0 | LY13: 0 | LZ13: 0 | MA13: 0 | MB13: 0 | MC13: 0 | MD13: 0 | ME13: 0
G14: 실행
F15: MPD cable 포설(Duct 포함) | G15: 계획 | H15: 0 | I15: 0 | J15: 0 | K15: 0 | L15: 0 | M15: 0 | N15: 0 | O15: 0 | P15: 0 | Q15: 0 | R15: 0 | S15: 0 | T15: 0 | U15: 0 | V15: 0 | W15: 0 | X15: 0 | Y15: 0 | Z15: 0 | AA15: 0 | AB15: 0 | AC15: 0 | AD15: 0 | AE15: 0 | AF15: 0 | AG15: 0 | AH15: 0 | AI15: 0 | AJ15: 0 | AK15: 0 | AL15: 1 | AM15: 1 | AN15: 1 | AO15: 0 | AP15: 0 | AQ15: 0 | AR15: 0 | AS15: 0 | AT15: 0 | AU15: 0 | AV15: 0 | AW15: 0 | AX15: 0 | AY15: 0 | AZ15: 0 | BA15: 0 | BB15: 0 | BC15: 0 | BD15: 0 | BE15: 0 | BF15: 0 | BG15: 0 | BH15: 0 | BI15: 0 | BJ15: 0 | BK15: 0 | BL15: 0 | BM15: 0 | BN15: 0 | BO15: 0 | BP15: 0 | BQ15: 0 | BR15: 0 | BS15: 0 | BT15: 0 | BU15: 0 | BV15: 0 | BW15: 2 | BX15: 2 | BY15: 2 | BZ15: 0 | CA15: 0 | CB15: 0 | CC15: 0 | CD15: 0 | CE15: 0 | CF15: 0 | CG15: 0 | CH15: 0 | CI15: 0 | CJ15: 0 | CK15: 0 | CL15: 0 | CM15: 0 | CN15: 0 | CO15: 0 | CP15: 0 | CQ15: 0 | CR15: 0 | CS15: 0 | CT15: 0 | CU15: 0 | CV15: 0 | CW15: 0 | CX15: 0 | CY15: 0 | CZ15: 0 | DA15: 0 | DB15: 0 | DC15: 0 | DD15: 0 | DE15: 0 | DF15: 0 | DG15: 0 | DH15: 0 | DI15: 0 | DJ15: 0 | DK15: 0 | DL15: 0 | DM15: 0 | DN15: 0 | DO15: 0 | DP15: 0 | DQ15: 0 | DR15: 0 | DS15: 0 | DT15: 0 | DU15: 0 | DV15: 0 | DW15: 0 | DX15: 0 | DY15: 0 | DZ15: 0 | EA15: 0 | EB15: 0 | EC15: 0 | ED15: 0 | EE15: 0 | EF15: 0 | EG15: 0 | EH15: 0 | EI15: 0 | EJ15: 0 | EK15: 0 | EL15: 0 | EM15: 0 | EN15: 0 | EO15: 0 | EP15: 0 | EQ15: 0 | ER15: 0 | ES15: 0 | ET15: 0 | EU15: 0 | EV15: 0 | EW15: 0 | EX15: 0 | EY15: 0 | EZ15: 0 | FA15: 0 | FB15: 0 | FC15: 0 | FD15: 0 | FE15: 0 | FF15: 0 | FG15: 0 | FH15: 0 | FI15: 0 | FJ15: 0 | FK15: 0 | FL15: 0 | FM15: 0 | FN15: 0 | FO15: 0 | FP15: 0 | FQ15: 0 | FR15: 0 | FS15: 0 | FT15: 0 | FU15: 0 | FV15: 0 | FW15: 0 | FX15: 0 | FY15: 0 | FZ15: 0 | GA15: 0 | GB15: 0 | GC15: 0 | GD15: 0 | GE15: 0 | GF15: 0 | GG15: 0 | GH15: 0 | GI15: 0 | GJ15: 0 | GK15: 0 | GL15: 0 | GM15: 0 | GN15: 0 | GO15: 0 | GP15: 0 | GQ15: 0 | GR15: 0 | GS15: 0 | GT15: 0 | GU15: 0 | GV15: 0 | GW15: 0 | GX15: 0 | GY15: 0 | GZ15: 0 | HA15: 0 | HB15: 0 | HC15: 0 | HD15: 0 | HE15: 0 | HF15: 0 | HG15: 0 | HH15: 0 | HI15: 0 | HJ15: 0 | HK15: 0 | HL15: 0 | HM15: 0 | HN15: 0 | HO15: 0 | HP15: 0 | HQ15: 0 | HR15: 0 | HS15: 0 | HT15: 0 | HU15: 0 | HV15: 0 | HW15: 0 | HX15: 0 | HY15: 0 | HZ15: 0 | IA15: 0 | IB15: 0 | IC15: 0 | ID15: 0 | IE15: 0 | IF15: 0 | IG15: 0 | IH15: 0 | II15: 0 | IJ15: 0 | IK15: 0 | IL15: 0 | IM15: 0 | IN15: 0 | IO15: 0 | IP15: 0 | IQ15: 0 | IR15: 0 | IS15: 0 | IT15: 0 | IU15: 0 | IV15: 0 | IW15: 0 | IX15: 0 | IY15: 0 | IZ15: 0 | JA15: 0 | JB15: 0 | JC15: 0 | JD15: 0 | JE15: 0 | JF15: 0 | JG15: 0 | JH15: 0 | JI15: 0 | JJ15: 0 | JK15: 0 | JL15: 0 | JM15: 0 | JN15: 0 | JO15: 0 | JP15: 0 | JQ15: 0 | JR15: 0 | JS15: 0 | JT15: 0 | JU15: 0 | JV15: 0 | JW15: 0 | JX15: 0 | JY15: 0 | JZ15: 0 | KA15: 0 | KB15: 0 | KC15: 0 | KD15: 0 | KE15: 0 | KF15: 0 | KG15: 0 | KH15: 0 | KI15: 0 | KJ15: 0 | KK15: 0 | KL15: 0 | KM15: 0 | KN15: 0 | KO15: 0 | KP15: 0 | KQ15: 0 | KR15: 0 | KS15: 0 | KT15: 0 | KU15: 0 | KV15: 0 | KW15: 0 | KX15: 0 | KY15: 0 | KZ15: 0 | LA15: 0 | LB15: 0 | LC15: 0 | LD15: 0 | LE15: 0 | LF15: 0 | LG15: 0 | LH15: 0 | LI15: 0 | LJ15: 0 | LK15: 0 | LL15: 0 | LM15: 0 | LN15: 0 | LO15: 0 | LP15: 0 | LQ15: 0 | LR15: 0 | LS15: 0 | LT15: 0 | LU15: 0 | LV15: 0 | LW15: 0 | LX15: 0 | LY15: 0 | LZ15: 0 | MA15: 0 | MB15: 0 | MC15: 0 | MD15: 0 | ME15: 0
G16: 실행
F17: Turn-On | G17: 계획 | H17: 0 | I17: 0 | J17: 0 | K17: 0 | L17: 0 | M17: 0 | N17: 0 | O17: 0 | P17: 0 | Q17: 0 | R17: 0 | S17: 0 | T17: 0 | U17: 0 | V17: 0 | W17: 0 | X17: 0 | Y17: 0 | Z17: 0 | AA17: 0 | AB17: 0 | AC17: 0 | AD17: 0 | AE17: 0 | AF17: 0 | AG17: 0 | AH17: 0 | AI17: 0 | AJ17: 0 | AK17: 0 | AL17: 0 | AM17: 0 | AN17: 0 | AO17: 1 | AP17: 0 | AQ17: 0 | AR17: 0 | AS17: 0 | AT17: 0 | AU17: 0 | AV17: 0 | AW17: 0 | AX17: 0 | AY17: 0 | AZ17: 0 | BA17: 0 | BB17: 0 | BC17: 0 | BD17: 0 | BE17: 0 | BF17: 0 | BG17: 0 | BH17: 0 | BI17: 0 | BJ17: 0 | BK17: 0 | BL17: 0 | BM17: 0 | BN17: 0 | BO17: 0 | BP17: 0 | BQ17: 0 | BR17: 0 | BS17: 0 | BT17: 0 | BU17: 0 | BV17: 0 | BW17: 0 | BX17: 0 | BY17: 0 | BZ17: 0 | CA17: 0 | CB17: 0 | CC17: 0 | CD17: 0 | CE17: 0 | CF17: 0 | CG17: 0 | CH17: 0 | CI17: 0 | CJ17: 0 | CK17: 0 | CL17: 0 | CM17: 0 | CN17: 0 | CO17: 0 | CP17: 0 | CQ17: 0 | CR17: 0 | CS17: 0 | CT17: 0 | CU17: 0 | CV17: 0 | CW17: 0 | CX17: 0 | CY17: 0 | CZ17: 0 | DA17: 0 | DB17: 0 | DC17: 0 | DD17: 0 | DE17: 0 | DF17: 0 | DG17: 0 | DH17: 0 | DI17: 0 | DJ17: 0 | DK17: 0 | DL17: 0 | DM17: 0 | DN17: 0 | DO17: 0 | DP17: 0 | DQ17: 0 | DR17: 0 | DS17: 0 | DT17: 0 | DU17: 0 | DV17: 0 | DW17: 0 | DX17: 0 | DY17: 0 | DZ17: 0 | EA17: 0 | EB17: 0 | EC17: 0 | ED17: 0 | EE17: 0 | EF17: 0 | EG17: 0 | EH17: 0 | EI17: 0 | EJ17: 0 | EK17: 0 | EL17: 0 | EM17: 0 | EN17: 0 | EO17: 0 | EP17: 0 | EQ17: 0 | ER17: 0 | ES17: 0 | ET17: 0 | EU17: 0 | EV17: 0 | EW17: 0 | EX17: 0 | EY17: 0 | EZ17: 0 | FA17: 0 | FB17: 0 | FC17: 0 | FD17: 0 | FE17: 0 | FF17: 0 | FG17: 0 | FH17: 0 | FI17: 0 | FJ17: 0 | FK17: 0 | FL17: 0 | FM17: 0 | FN17: 0 | FO17: 0 | FP17: 0 | FQ17: 0 | FR17: 0 | FS17: 0 | FT17: 0 | FU17: 0 | FV17: 0 | FW17: 0 | FX17: 0 | FY17: 0 | FZ17: 0 | GA17: 0 | GB17: 0 | GC17: 0 | GD17: 0 | GE17: 0 | GF17: 0 | GG17: 0 | GH17: 0 | GI17: 0 | GJ17: 0 | GK17: 0 | GL17: 0 | GM17: 0 | GN17: 0 | GO17: 0 | GP17: 0 | GQ17: 0 | GR17: 0 | GS17: 0 | GT17: 0 | GU17: 0 | GV17: 0 | GW17: 0 | GX17: 0 | GY17: 0 | GZ17: 0 | HA17: 0 | HB17: 0 | HC17: 0 | HD17: 0 | HE17: 0 | HF17: 0 | HG17: 0 | HH17: 0 | HI17: 0 | HJ17: 0 | HK17: 0 | HL17: 0 | HM17: 0 | HN17: 0 | HO17: 0 | HP17: 0 | HQ17: 0 | HR17: 0 | HS17: 0 | HT17: 0 | HU17: 0 | HV17: 0 | HW17: 0 | HX17: 0 | HY17: 0 | HZ17: 0 | IA17: 0 | IB17: 0 | IC17: 0 | ID17: 0 | IE17: 0 | IF17: 0 | IG17: 0 | IH17: 0 | II17: 0 | IJ17: 0 | IK17: 0 | IL17: 0 | IM17: 0 | IN17: 0 | IO17: 0 | IP17: 0 | IQ17: 0 | IR17: 0 | IS17: 0 | IT17: 0 | IU17: 0 | IV17: 0 | IW17: 0 | IX17: 0 | IY17: 0 | IZ17: 0 | JA17: 0 | JB17: 0 | JC17: 0 | JD17: 0 | JE17: 0 | JF17: 0 | JG17: 0 | JH17: 0 | JI17: 0 | JJ17: 0 | JK17: 0 | JL17: 0 | JM17: 0 | JN17: 0 | JO17: 0 | JP17: 0 | JQ17: 0 | JR17: 0 | JS17: 0 | JT17: 0 | JU17: 0 | JV17: 0 | JW17: 0 | JX17: 0 | JY17: 0 | JZ17: 0 | KA17: 0 | KB17: 0 | KC17: 0 | KD17: 0 | KE17: 0 | KF17: 0 | KG17: 0 | KH17: 0 | KI17: 0 | KJ17: 0 | KK17: 0 | KL17: 0 | KM17: 0 | KN17: 0 | KO17: 0 | KP17: 0 | KQ17: 0 | KR17: 0 | KS17: 0 | KT17: 0 | KU17: 0 | KV17: 0 | KW17: 0 | KX17: 0 | KY17: 0 | KZ17: 0 | LA17: 0 | LB17: 0 | LC17: 0 | LD17: 0 | LE17: 0 | LF17: 0 | LG17: 0 | LH17: 0 | LI17: 0 | LJ17: 0 | LK17: 0 | LL17: 0 | LM17: 0 | LN17: 0 | LO17: 0 | LP17: 0 | LQ17: 0 | LR17: 0 | LS17: 0 | LT17: 0 | LU17: 0 | LV17: 0 | LW17: 0 | LX17: 0 | LY17: 0 | LZ17: 0 | MA17: 0 | MB17: 0 | MC17: 0 | MD17: 0 | ME17: 0
G18: 실행
F19: I/O 확인 | G19: 계획 | H19: 0 | I19: 0 | J19: 0 | K19: 0 | L19: 0 | M19: 0 | N19: 0 | O19: 0 | P19: 0 | Q19: 0 | R19: 0 | S19: 0 | T19: 0 | U19: 0 | V19: 0 | W19: 0 | X19: 0 | Y19: 0 | Z19: 0 | AA19: 0 | AB19: 0 | AC19: 0 | AD19: 0 | AE19: 0 | AF19: 0 | AG19: 0 | AH19: 0 | AI19: 0 | AJ19: 0 | AK19: 0 | AL19: 0 | AM19: 0 | AN19: 0 | AO19: 0 | AP19: 1 | AQ19: 0 | AR19: 1 | AS19: 1 | AT19: 1 | AU19: 0 | AV19: 0 | AW19: 0 | AX19: 0 | AY19: 0 | AZ19: 0 | BA19: 0 | BB19: 0 | BC19: 0 | BD19: 0 | BE19: 0 | BF19: 0 | BG19: 0 | BH19: 0 | BI19: 0 | BJ19: 0 | BK19: 0 | BL19: 0 | BM19: 0 | BN19: 0 | BO19: 0 | BP19: 0 | BQ19: 0 | BR19: 0 | BS19: 0 | BT19: 0 | BU19: 0 | BV19: 0 | BW19: 0 | BX19: 0 | BY19: 0 | BZ19: 0 | CA19: 2 | CB19: 2 | CC19: 2 | CD19: 2 | CE19: 0 | CF19: 0 | CG19: 0 | CH19: 0 | CI19: 0 | CJ19: 0 | CK19: 0 | CL19: 0 | CM19: 0 | CN19: 0 | CO19: 0 | CP19: 0 | CQ19: 0 | CR19: 0 | CS19: 0 | CT19: 0 | CU19: 0 | CV19: 0 | CW19: 0 | CX19: 0 | CY19: 0 | CZ19: 0 | DA19: 0 | DB19: 0 | DC19: 0 | DD19: 0 | DE19: 0 | DF19: 0 | DG19: 0 | DH19: 0 | DI19: 0 | DJ19: 0 | DK19: 0 | DL19: 0 | DM19: 0 | DN19: 0 | DO19: 0 | DP19: 0 | DQ19: 0 | DR19: 0 | DS19: 0 | DT19: 0 | DU19: 0 | DV19: 0 | DW19: 0 | DX19: 0 | DY19: 0 | DZ19: 0 | EA19: 0 | EB19: 0 | EC19: 0 | ED19: 0 | EE19: 0 | EF19: 0 | EG19: 0 | EH19: 0 | EI19: 0 | EJ19: 0 | EK19: 0 | EL19: 0 | EM19: 0 | EN19: 0 | EO19: 0 | EP19: 0 | EQ19: 0 | ER19: 0 | ES19: 0 | ET19: 0 | EU19: 0 | EV19: 0 | EW19: 0 | EX19: 0 | EY19: 0 | EZ19: 0 | FA19: 0 | FB19: 0 | FC19: 0 | FD19: 0 | FE19: 0 | FF19: 0 | FG19: 0 | FH19: 0 | FI19: 0 | FJ19: 0 | FK19: 0 | FL19: 0 | FM19: 0 | FN19: 0 | FO19: 0 | FP19: 0 | FQ19: 0 | FR19: 0 | FS19: 0 | FT19: 0 | FU19: 0 | FV19: 0 | FW19: 0 | FX19: 0 | FY19: 0 | FZ19: 0 | GA19: 0 | GB19: 0 | GC19: 0 | GD19: 0 | GE19: 0 | GF19: 0 | GG19: 0 | GH19: 0 | GI19: 0 | GJ19: 0 | GK19: 0 | GL19: 0 | GM19: 0 | GN19: 0 | GO19: 0 | GP19: 0 | GQ19: 0 | GR19: 0 | GS19: 0 | GT19: 0 | GU19: 0 | GV19: 0 | GW19: 0 | GX19: 0 | GY19: 0 | GZ19: 0 | HA19: 0 | HB19: 0 | HC19: 0 | HD19: 0 | HE19: 0 | HF19: 0 | HG19: 0 | HH19: 0 | HI19: 0 | HJ19: 0 | HK19: 0 | HL19: 0 | HM19: 0 | HN19: 0 | HO19: 0 | HP19: 0 | HQ19: 0 | HR19: 0 | HS19: 0 | HT19: 0 | HU19: 0 | HV19: 0 | HW19: 0 | HX19: 0 | HY19: 0 | HZ19: 0 | IA19: 0 | IB19: 0 | IC19: 0 | ID19: 0 | IE19: 0 | IF19: 0 | IG19: 0 | IH19: 0 | II19: 0 | IJ19: 0 | IK19: 0 | IL19: 0 | IM19: 0 | IN19: 0 | IO19: 0 | IP19: 0 | IQ19: 0 | IR19: 0 | IS19: 0 | IT19: 0 | IU19: 0 | IV19: 0 | IW19: 0 | IX19: 0 | IY19: 0 | IZ19: 0 | JA19: 0 | JB19: 0 | JC19: 0 | JD19: 0 | JE19: 0 | JF19: 0 | JG19: 0 | JH19: 0 | JI19: 0 | JJ19: 0 | JK19: 0 | JL19: 0 | JM19: 0 | JN19: 0 | JO19: 0 | JP19: 0 | JQ19: 0 | JR19: 0 | JS19: 0 | JT19: 0 | JU19: 0 | JV19: 0 | JW19: 0 | JX19: 0 | JY19: 0 | JZ19: 0 | KA19: 0 | KB19: 0 | KC19: 0 | KD19: 0 | KE19: 0 | KF19: 0 | KG19: 0 | KH19: 0 | KI19: 0 | KJ19: 0 | KK19: 0 | KL19: 0 | KM19: 0 | KN19: 0 | KO19: 0 | KP19: 0 | KQ19: 0 | KR19: 0 | KS19: 0 | KT19: 0 | KU19: 0 | KV19: 0 | KW19: 0 | KX19: 0 | KY19: 0 | KZ19: 0 | LA19: 0 | LB19: 0 | LC19: 0 | LD19: 0 | LE19: 0 | LF19: 0 | LG19: 0 | LH19: 0 | LI19: 0 | LJ19: 0 | LK19: 0 | LL19: 0 | LM19: 0 | LN19: 0 | LO19: 0 | LP19: 0 | LQ19: 0 | LR19: 0 | LS19: 0 | LT19: 0 | LU19: 0 | LV19: 0 | LW19: 0 | LX19: 0 | LY19: 0 | LZ19: 0 | MA19: 0 | MB19: 0 | MC19: 0 | MD19: 0 | ME19: 0
G20: 실행
C21: 단동 평가(제어) | F21: Pumping / Vent (Leak check) | G21: 계획 | H21: 0 | I21: 0 | J21: 0 | K21: 0 | L21: 0 | M21: 0 | N21: 0 | O21: 0 | P21: 0 | Q21: 0 | R21: 0 | S21: 0 | T21: 0 | U21: 0 | V21: 0 | W21: 0 | X21: 0 | Y21: 0 | Z21: 0 | AA21: 0 | AB21: 0 | AC21: 0 | AD21: 0 | AE21: 0 | AF21: 0 | AG21: 0 | AH21: 0 | AI21: 0 | AJ21: 0 | AK21: 0 | AL21: 0 | AM21: 0 | AN21: 0 | AO21: 0 | AP21: 0 | AQ21: 0 | AR21: 0 | AS21: 0 | AT21: 0 | AU21: 1 | AV21: 1 | AW21: 1 | AX21: 0 | AY21: 0 | AZ21: 0 | BA21: 0 | BB21: 0 | BC21: 0 | BD21: 0 | BE21: 0 | BF21: 0 | BG21: 0 | BH21: 0 | BI21: 0 | BJ21: 0 | BK21: 0 | BL21: 0 | BM21: 0 | BN21: 0 | BO21: 0 | BP21: 0 | BQ21: 0 | BR21: 0 | BS21: 0 | BT21: 0 | BU21: 0 | BV21: 0 | BW21: 0 | BX21: 0 | BY21: 0 | BZ21: 0 | CA21: 0 | CB21: 0 | CC21: 0 | CD21: 0 | CE21: 0 | CF21: 2 | CG21: 0 | CH21: 2 | CI21: 0 | CJ21: 0 | CK21: 0 | CL21: 0 | CM21: 0 | CN21: 0 | CO21: 0 | CP21: 0 | CQ21: 0 | CR21: 0 | CS21: 0 | CT21: 0 | CU21: 0 | CV21: 0 | CW21: 0 | CX21: 0 | CY21: 0 | CZ21: 0 | DA21: 0 | DB21: 0 | DC21: 0 | DD21: 0 | DE21: 0 | DF21: 0 | DG21: 0 | DH21: 0 | DI21: 0 | DJ21: 0 | DK21: 0 | DL21: 0 | DM21: 0 | DN21: 0 | DO21: 0 | DP21: 0 | DQ21: 0 | DR21: 0 | DS21: 0 | DT21: 0 | DU21: 0 | DV21: 0 | DW21: 0 | DX21: 0 | DY21: 0 | DZ21: 0 | EA21: 0 | EB21: 0 | EC21: 0 | ED21: 0 | EE21: 0 | EF21: 0 | EG21: 0 | EH21: 0 | EI21: 0 | EJ21: 0 | EK21: 0 | EL21: 0 | EM21: 0 | EN21: 0 | EO21: 0 | EP21: 0 | EQ21: 0 | ER21: 0 | ES21: 0 | ET21: 0 | EU21: 0 | EV21: 0 | EW21: 0 | EX21: 0 | EY21: 0 | EZ21: 0 | FA21: 0 | FB21: 0 | FC21: 0 | FD21: 0 | FE21: 0 | FF21: 0 | FG21: 0 | FH21: 0 | FI21: 0 | FJ21: 0 | FK21: 0 | FL21: 0 | FM21: 0 | FN21: 0 | FO21: 0 | FP21: 0 | FQ21: 0 | FR21: 0 | FS21: 0 | FT21: 0 | FU21: 0 | FV21: 0 | FW21: 0 | FX21: 0 | FY21: 0 | FZ21: 0 | GA21: 0 | GB21: 0 | GC21: 0 | GD21: 0 | GE21: 0 | GF21: 0 | GG21: 0 | GH21: 0 | GI21: 0 | GJ21: 0 | GK21: 0 | GL21: 0 | GM21: 0 | GN21: 0 | GO21: 0 | GP21: 0 | GQ21: 0 | GR21: 0 | GS21: 0 | GT21: 0 | GU21: 0 | GV21: 0 | GW21: 0 | GX21: 0 | GY21: 0 | GZ21: 0 | HA21: 0 | HB21: 0 | HC21: 0 | HD21: 0 | HE21: 0 | HF21: 0 | HG21: 0 | HH21: 0 | HI21: 0 | HJ21: 0 | HK21: 0 | HL21: 0 | HM21: 0 | HN21: 0 | HO21: 0 | HP21: 0 | HQ21: 0 | HR21: 0 | HS21: 0 | HT21: 0 | HU21: 0 | HV21: 0 | HW21: 0 | HX21: 0 | HY21: 0 | HZ21: 0 | IA21: 0 | IB21: 0 | IC21: 0 | ID21: 0 | IE21: 0 | IF21: 0 | IG21: 0 | IH21: 0 | II21: 0 | IJ21: 0 | IK21: 0 | IL21: 0 | IM21: 0 | IN21: 0 | IO21: 0 | IP21: 0 | IQ21: 0 | IR21: 0 | IS21: 0 | IT21: 0 | IU21: 0 | IV21: 0 | IW21: 0 | IX21: 0 | IY21: 0 | IZ21: 0 | JA21: 0 | JB21: 0 | JC21: 0 | JD21: 0 | JE21: 0 | JF21: 0 | JG21: 0 | JH21: 0 | JI21: 0 | JJ21: 0 | JK21: 0 | JL21: 0 | JM21: 0 | JN21: 0 | JO21: 0 | JP21: 0 | JQ21: 0 | JR21: 0 | JS21: 0 | JT21: 0 | JU21: 0 | JV21: 0 | JW21: 0 | JX21: 0 | JY21: 0 | JZ21: 0 | KA21: 0 | KB21: 0 | KC21: 0 | KD21: 0 | KE21: 0 | KF21: 0 | KG21: 0 | KH21: 0 | KI21: 0 | KJ21: 0 | KK21: 0 | KL21: 0 | KM21: 0 | KN21: 0 | KO21: 0 | KP21: 0 | KQ21: 0 | KR21: 0 | KS21: 0 | KT21: 0 | KU21: 0 | KV21: 0 | KW21: 0 | KX21: 0 | KY21: 0 | KZ21: 0 | LA21: 0 | LB21: 0 | LC21: 0 | LD21: 0 | LE21: 0 | LF21: 0 | LG21: 0 | LH21: 0 | LI21: 0 | LJ21: 0 | LK21: 0 | LL21: 0 | LM21: 0 | LN21: 0 | LO21: 0 | LP21: 0 | LQ21: 0 | LR21: 0 | LS21: 0 | LT21: 0 | LU21: 0 | LV21: 0 | LW21: 0 | LX21: 0 | LY21: 0 | LZ21: 0 | MA21: 0 | MB21: 0 | MC21: 0 | MD21: 0 | ME21: 0
G22: 실행
F23: Isolator Tunning (대기/진공) | G23: 계획 | H23: 0 | I23: 0 | J23: 0 | K23: 0 | L23: 0 | M23: 0 | N23: 0 | O23: 0 | P23: 0 | Q23: 0 | R23: 0 | S23: 0 | T23: 0 | U23: 0 | V23: 0 | W23: 0 | X23: 0 | Y23: 0 | Z23: 0 | AA23: 0 | AB23: 0 | AC23: 0 | AD23: 0 | AE23: 0 | AF23: 0 | AG23: 0 | AH23: 0 | AI23: 0 | AJ23: 0 | AK23: 0 | AL23: 0 | AM23: 0 | AN23: 0 | AO23: 0 | AP23: 0 | AQ23: 0 | AR23: 0 | AS23: 0 | AT23: 0 | AU23: 0 | AV23: 0 | AW23: 0 | AX23: 0 | AY23: 1 | AZ23: 1 | BA23: 0 | BB23: 0 | BC23: 0 | BD23: 0 | BE23: 0 | BF23: 0 | BG23: 0 | BH23: 0 | BI23: 0 | BJ23: 0 | BK23: 0 | BL23: 0 | BM23: 0 | BN23: 0 | BO23: 0 | BP23: 0 | BQ23: 0 | BR23: 0 | BS23: 0 | BT23: 0 | BU23: 0 | BV23: 0 | BW23: 0 | BX23: 0 | BY23: 0 | BZ23: 0 | CA23: 0 | CB23: 0 | CC23: 0 | CD23: 0 | CE23: 0 | CF23: 0 | CG23: 0 | CH23: 0 | CI23: 0 | CJ23: 2 | CK23: 2 | CL23: 0 | CM23: 0 | CN23: 0 | CO23: 0 | CP23: 0 | CQ23: 0 | CR23: 0 | CS23: 0 | CT23: 0 | CU23: 0 | CV23: 0 | CW23: 0 | CX23: 0 | CY23: 0 | CZ23: 0 | DA23: 0 | DB23: 0 | DC23: 0 | DD23: 0 | DE23: 0 | DF23: 0 | DG23: 0 | DH23: 0 | DI23: 0 | DJ23: 0 | DK23: 0 | DL23: 0 | DM23: 0 | DN23: 0 | DO23: 0 | DP23: 0 | DQ23: 0 | DR23: 0 | DS23: 0 | DT23: 0 | DU23: 0 | DV23: 0 | DW23: 0 | DX23: 0 | DY23: 0 | DZ23: 0 | EA23: 0 | EB23: 0 | EC23: 0 | ED23: 0 | EE23: 0 | EF23: 0 | EG23: 0 | EH23: 0 | EI23: 0 | EJ23: 0 | EK23: 0 | EL23: 0 | EM23: 0 | EN23: 0 | EO23: 0 | EP23: 0 | EQ23: 0 | ER23: 0 | ES23: 0 | ET23: 0 | EU23: 0 | EV23: 0 | EW23: 0 | EX23: 0 | EY23: 0 | EZ23: 0 | FA23: 0 | FB23: 0 | FC23: 0 | FD23: 0 | FE23: 0 | FF23: 0 | FG23: 0 | FH23: 0 | FI23: 0 | FJ23: 0 | FK23: 0 | FL23: 0 | FM23: 0 | FN23: 0 | FO23: 0 | FP23: 0 | FQ23: 0 | FR23: 0 | FS23: 0 | FT23: 0 | FU23: 0 | FV23: 0 | FW23: 0 | FX23: 0 | FY23: 0 | FZ23: 0 | GA23: 0 | GB23: 0 | GC23: 0 | GD23: 0 | GE23: 0 | GF23: 0 | GG23: 0 | GH23: 0 | GI23: 0 | GJ23: 0 | GK23: 0 | GL23: 0 | GM23: 0 | GN23: 0 | GO23: 0 | GP23: 0 | GQ23: 0 | GR23: 0 | GS23: 0 | GT23: 0 | GU23: 0 | GV23: 0 | GW23: 0 | GX23: 0 | GY23: 0 | GZ23: 0 | HA23: 0 | HB23: 0 | HC23: 0 | HD23: 0 | HE23: 0 | HF23: 0 | HG23: 0 | HH23: 0 | HI23: 0 | HJ23: 0 | HK23: 0 | HL23: 0 | HM23: 0 | HN23: 0 | HO23: 0 | HP23: 0 | HQ23: 0 | HR23: 0 | HS23: 0 | HT23: 0 | HU23: 0 | HV23: 0 | HW23: 0 | HX23: 0 | HY23: 0 | HZ23: 0 | IA23: 0 | IB23: 0 | IC23: 0 | ID23: 0 | IE23: 0 | IF23: 0 | IG23: 0 | IH23: 0 | II23: 0 | IJ23: 0 | IK23: 0 | IL23: 0 | IM23: 0 | IN23: 0 | IO23: 0 | IP23: 0 | IQ23: 0 | IR23: 0 | IS23: 0 | IT23: 0 | IU23: 0 | IV23: 0 | IW23: 0 | IX23: 0 | IY23: 0 | IZ23: 0 | JA23: 0 | JB23: 0 | JC23: 0 | JD23: 0 | JE23: 0 | JF23: 0 | JG23: 0 | JH23: 0 | JI23: 0 | JJ23: 0 | JK23: 0 | JL23: 0 | JM23: 0 | JN23: 0 | JO23: 0 | JP23: 0 | JQ23: 0 | JR23: 0 | JS23: 0 | JT23: 0 | JU23: 0 | JV23: 0 | JW23: 0 | JX23: 0 | JY23: 0 | JZ23: 0 | KA23: 0 | KB23: 0 | KC23: 0 | KD23: 0 | KE23: 0 | KF23: 0 | KG23: 0 | KH23: 0 | KI23: 0 | KJ23: 0 | KK23: 0 | KL23: 0 | KM23: 0 | KN23: 0 | KO23: 0 | KP23: 0 | KQ23: 0 | KR23: 0 | KS23: 0 | KT23: 0 | KU23: 0 | KV23: 0 | KW23: 0 | KX23: 0 | KY23: 0 | KZ23: 0 | LA23: 0 | LB23: 0 | LC23: 0 | LD23: 0 | LE23: 0 | LF23: 0 | LG23: 0 | LH23: 0 | LI23: 0 | LJ23: 0 | LK23: 0 | LL23: 0 | LM23: 0 | LN23: 0 | LO23: 0 | LP23: 0 | LQ23: 0 | LR23: 0 | LS23: 0 | LT23: 0 | LU23: 0 | LV23: 0 | LW23: 0 | LX23: 0 | LY23: 0 | LZ23: 0 | MA23: 0 | MB23: 0 | MC23: 0 | MD23: 0 | ME23: 0
G24: 실행
F25: Pin-Up, down & Chucking, Pin level setting | G25: 계획 | H25: 0 | I25: 0 | J25: 0 | K25: 0 | L25: 0 | M25: 0 | N25: 0 | O25: 0 | P25: 0 | Q25: 0 | R25: 0 | S25: 0 | T25: 0 | U25: 0 | V25: 0 | W25: 0 | X25: 0 | Y25: 0 | Z25: 0 | AA25: 0 | AB25: 0 | AC25: 0 | AD25: 0 | AE25: 0 | AF25: 0 | AG25: 0 | AH25: 0 | AI25: 0 | AJ25: 0 | AK25: 0 | AL25: 0 | AM25: 0 | AN25: 0 | AO25: 0 | AP25: 0 | AQ25: 0 | AR25: 0 | AS25: 0 | AT25: 0 | AU25: 0 | AV25: 0 | AW25: 0 | AX25: 0 | AY25: 0 | AZ25: 0 | BA25: 1 | BB25: 1 | BC25: 0 | BD25: 0 | BE25: 0 | BF25: 0 | BG25: 0 | BH25: 0 | BI25: 0 | BJ25: 0 | BK25: 0 | BL25: 0 | BM25: 0 | BN25: 0 | BO25: 0 | BP25: 0 | BQ25: 0 | BR25: 0 | BS25: 0 | BT25: 0 | BU25: 0 | BV25: 0 | BW25: 0 | BX25: 0 | BY25: 0 | BZ25: 0 | CA25: 0 | CB25: 0 | CC25: 0 | CD25: 0 | CE25: 0 | CF25: 0 | CG25: 0 | CH25: 0 | CI25: 0 | CJ25: 0 | CK25: 0 | CL25: 0 | CM25: 2 | CN25: 0 | CO25: 0 | CP25: 0 | CQ25: 0 | CR25: 0 | CS25: 0 | CT25: 0 | CU25: 0 | CV25: 0 | CW25: 0 | CX25: 0 | CY25: 0 | CZ25: 0 | DA25: 0 | DB25: 0 | DC25: 0 | DD25: 0 | DE25: 0 | DF25: 0 | DG25: 0 | DH25: 0 | DI25: 0 | DJ25: 0 | DK25: 0 | DL25: 0 | DM25: 0 | DN25: 0 | DO25: 0 | DP25: 0 | DQ25: 0 | DR25: 0 | DS25: 0 | DT25: 0 | DU25: 0 | DV25: 0 | DW25: 0 | DX25: 0 | DY25: 0 | DZ25: 0 | EA25: 0 | EB25: 0 | EC25: 0 | ED25: 0 | EE25: 0 | EF25: 0 | EG25: 0 | EH25: 0 | EI25: 0 | EJ25: 0 | EK25: 0 | EL25: 0 | EM25: 0 | EN25: 0 | EO25: 0 | EP25: 0 | EQ25: 0 | ER25: 0 | ES25: 0 | ET25: 0 | EU25: 0 | EV25: 0 | EW25: 0 | EX25: 0 | EY25: 0 | EZ25: 0 | FA25: 0 | FB25: 0 | FC25: 0 | FD25: 0 | FE25: 0 | FF25: 0 | FG25: 0 | FH25: 0 | FI25: 0 | FJ25: 0 | FK25: 0 | FL25: 0 | FM25: 0 | FN25: 0 | FO25: 0 | FP25: 0 | FQ25: 0 | FR25: 0 | FS25: 0 | FT25: 0 | FU25: 0 | FV25: 0 | FW25: 0 | FX25: 0 | FY25: 0 | FZ25: 0 | GA25: 0 | GB25: 0 | GC25: 0 | GD25: 0 | GE25: 0 | GF25: 0 | GG25: 0 | GH25: 0 | GI25: 0 | GJ25: 0 | GK25: 0 | GL25: 0 | GM25: 0 | GN25: 0 | GO25: 0 | GP25: 0 | GQ25: 0 | GR25: 0 | GS25: 0 | GT25: 0 | GU25: 0 | GV25: 0 | GW25: 0 | GX25: 0 | GY25: 0 | GZ25: 0 | HA25: 0 | HB25: 0 | HC25: 0 | HD25: 0 | HE25: 0 | HF25: 0 | HG25: 0 | HH25: 0 | HI25: 0 | HJ25: 0 | HK25: 0 | HL25: 0 | HM25: 0 | HN25: 0 | HO25: 0 | HP25: 0 | HQ25: 0 | HR25: 0 | HS25: 0 | HT25: 0 | HU25: 0 | HV25: 0 | HW25: 0 | HX25: 0 | HY25: 0 | HZ25: 0 | IA25: 0 | IB25: 0 | IC25: 0 | ID25: 0 | IE25: 0 | IF25: 0 | IG25: 0 | IH25: 0 | II25: 0 | IJ25: 0 | IK25: 0 | IL25: 0 | IM25: 0 | IN25: 0 | IO25: 0 | IP25: 0 | IQ25: 0 | IR25: 0 | IS25: 0 | IT25: 0 | IU25: 0 | IV25: 0 | IW25: 0 | IX25: 0 | IY25: 0 | IZ25: 0 | JA25: 0 | JB25: 0 | JC25: 0 | JD25: 0 | JE25: 0 | JF25: 0 | JG25: 0 | JH25: 0 | JI25: 0 | JJ25: 0 | JK25: 0 | JL25: 0 | JM25: 0 | JN25: 0 | JO25: 0 | JP25: 0 | JQ25: 0 | JR25: 0 | JS25: 0 | JT25: 0 | JU25: 0 | JV25: 0 | JW25: 0 | JX25: 0 | JY25: 0 | JZ25: 0 | KA25: 0 | KB25: 0 | KC25: 0 | KD25: 0 | KE25: 0 | KF25: 0 | KG25: 0 | KH25: 0 | KI25: 0 | KJ25: 0 | KK25: 0 | KL25: 0 | KM25: 0 | KN25: 0 | KO25: 0 | KP25: 0 | KQ25: 0 | KR25: 0 | KS25: 0 | KT25: 0 | KU25: 0 | KV25: 0 | KW25: 0 | KX25: 0 | KY25: 0 | KZ25: 0 | LA25: 0 | LB25: 0 | LC25: 0 | LD25: 0 | LE25: 0 | LF25: 0 | LG25: 0 | LH25: 0 | LI25: 0 | LJ25: 0 | LK25: 0 | LL25: 0 | LM25: 0 | LN25: 0 | LO25: 0 | LP25: 0 | LQ25: 0 | LR25: 0 | LS25: 0 | LT25: 0 | LU25: 0 | LV25: 0 | LW25: 0 | LX25: 0 | LY25: 0 | LZ25: 0 | MA25: 0 | MB25: 0 | MC25: 0 | MD25: 0 | ME25: 0
G26: 실행
F27: Stage Tunning (대기/진공, 프레스토, 주행축, Review축, LDS축) | G27: 계획 | H27: 0 | I27: 0 | J27: 0 | K27: 0 | L27: 0 | M27: 0 | N27: 0 | O27: 0 | P27: 0 | Q27: 0 | R27: 0 | S27: 0 | T27: 0 | U27: 0 | V27: 0 | W27: 0 | X27: 0 | Y27: 0 | Z27: 0 | AA27: 0 | AB27: 0 | AC27: 0 | AD27: 0 | AE27: 0 | AF27: 0 | AG27: 0 | AH27: 0 | AI27: 0 | AJ27: 0 | AK27: 0 | AL27: 0 | AM27: 0 | AN27: 0 | AO27: 0 | AP27: 0 | AQ27: 0 | AR27: 0 | AS27: 0 | AT27: 0 | AU27: 0 | AV27: 0 | AW27: 0 | AX27: 0 | AY27: 0 | AZ27: 0 | BA27: 0 | BB27: 0 | BC27: 1 | BD27: 1 | BE27: 0 | BF27: 0 | BG27: 0 | BH27: 0 | BI27: 0 | BJ27: 0 | BK27: 0 | BL27: 0 | BM27: 0 | BN27: 0 | BO27: 0 | BP27: 0 | BQ27: 0 | BR27: 0 | BS27: 0 | BT27: 0 | BU27: 0 | BV27: 0 | BW27: 0 | BX27: 0 | BY27: 0 | BZ27: 0 | CA27: 0 | CB27: 0 | CC27: 0 | CD27: 0 | CE27: 0 | CF27: 0 | CG27: 0 | CH27: 0 | CI27: 0 | CJ27: 0 | CK27: 0 | CL27: 0 | CM27: 0 | CN27: 0 | CO27: 2 | CP27: 0 | CQ27: 0 | CR27: 0 | CS27: 0 | CT27: 0 | CU27: 0 | CV27: 0 | CW27: 0 | CX27: 0 | CY27: 0 | CZ27: 0 | DA27: 0 | DB27: 0 | DC27: 0 | DD27: 0 | DE27: 0 | DF27: 0 | DG27: 0 | DH27: 0 | DI27: 0 | DJ27: 0 | DK27: 0 | DL27: 0 | DM27: 0 | DN27: 0 | DO27: 0 | DP27: 0 | DQ27: 0 | DR27: 0 | DS27: 0 | DT27: 0 | DU27: 0 | DV27: 0 | DW27: 0 | DX27: 0 | DY27: 0 | DZ27: 0 | EA27: 0 | EB27: 0 | EC27: 0 | ED27: 0 | EE27: 0 | EF27: 0 | EG27: 0 | EH27: 0 | EI27: 0 | EJ27: 0 | EK27: 0 | EL27: 0 | EM27: 0 | EN27: 0 | EO27: 0 | EP27: 0 | EQ27: 0 | ER27: 0 | ES27: 0 | ET27: 0 | EU27: 0 | EV27: 0 | EW27: 0 | EX27: 0 | EY27: 0 | EZ27: 0 | FA27: 0 | FB27: 0 | FC27: 0 | FD27: 0 | FE27: 0 | FF27: 0 | FG27: 0 | FH27: 0 | FI27: 0 | FJ27: 0 | FK27: 0 | FL27: 0 | FM27: 0 | FN27: 0 | FO27: 0 | FP27: 0 | FQ27: 0 | FR27: 0 | FS27: 0 | FT27: 0 | FU27: 0 | FV27: 0 | FW27: 0 | FX27: 0 | FY27: 0 | FZ27: 0 | GA27: 0 | GB27: 0 | GC27: 0 | GD27: 0 | GE27: 0 | GF27: 0 | GG27: 0 | GH27: 0 | GI27: 0 | GJ27: 0 | GK27: 0 | GL27: 0 | GM27: 0 | GN27: 0 | GO27: 0 | GP27: 0 | GQ27: 0 | GR27: 0 | GS27: 0 | GT27: 0 | GU27: 0 | GV27: 0 | GW27: 0 | GX27: 0 | GY27: 0 | GZ27: 0 | HA27: 0 | HB27: 0 | HC27: 0 | HD27: 0 | HE27: 0 | HF27: 0 | HG27: 0 | HH27: 0 | HI27: 0 | HJ27: 0 | HK27: 0 | HL27: 0 | HM27: 0 | HN27: 0 | HO27: 0 | HP27: 0 | HQ27: 0 | HR27: 0 | HS27: 0 | HT27: 0 | HU27: 0 | HV27: 0 | HW27: 0 | HX27: 0 | HY27: 0 | HZ27: 0 | IA27: 0 | IB27: 0 | IC27: 0 | ID27: 0 | IE27: 0 | IF27: 0 | IG27: 0 | IH27: 0 | II27: 0 | IJ27: 0 | IK27: 0 | IL27: 0 | IM27: 0 | IN27: 0 | IO27: 0 | IP27: 0 | IQ27: 0 | IR27: 0 | IS27: 0 | IT27: 0 | IU27: 0 | IV27: 0 | IW27: 0 | IX27: 0 | IY27: 0 | IZ27: 0 | JA27: 0 | JB27: 0 | JC27: 0 | JD27: 0 | JE27: 0 | JF27: 0 | JG27: 0 | JH27: 0 | JI27: 0 | JJ27: 0 | JK27: 0 | JL27: 0 | JM27: 0 | JN27: 0 | JO27: 0 | JP27: 0 | JQ27: 0 | JR27: 0 | JS27: 0 | JT27: 0 | JU27: 0 | JV27: 0 | JW27: 0 | JX27: 0 | JY27: 0 | JZ27: 0 | KA27: 0 | KB27: 0 | KC27: 0 | KD27: 0 | KE27: 0 | KF27: 0 | KG27: 0 | KH27: 0 | KI27: 0 | KJ27: 0 | KK27: 0 | KL27: 0 | KM27: 0 | KN27: 0 | KO27: 0 | KP27: 0 | KQ27: 0 | KR27: 0 | KS27: 0 | KT27: 0 | KU27: 0 | KV27: 0 | KW27: 0 | KX27: 0 | KY27: 0 | KZ27: 0 | LA27: 0 | LB27: 0 | LC27: 0 | LD27: 0 | LE27: 0 | LF27: 0 | LG27: 0 | LH27: 0 | LI27: 0 | LJ27: 0 | LK27: 0 | LL27: 0 | LM27: 0 | LN27: 0 | LO27: 0 | LP27: 0 | LQ27: 0 | LR27: 0 | LS27: 0 | LT27: 0 | LU27: 0 | LV27: 0 | LW27: 0 | LX27: 0 | LY27: 0 | LZ27: 0 | MA27: 0 | MB27: 0 | MC27: 0 | MD27: 0 | ME27: 0
G28: 실행
F29: 주행축/Review축 정밀도 측정(Interferrometer) - Center 상/하판만 측정시 4일 소요 | G29: 계획 | H29: 0 | I29: 0 | J29: 0 | K29: 0 | L29: 0 | M29: 0 | N29: 0 | O29: 0 | P29: 0 | Q29: 0 | R29: 0 | S29: 0 | T29: 0 | U29: 0 | V29: 0 | W29: 0 | X29: 0 | Y29: 0 | Z29: 0 | AA29: 0 | AB29: 0 | AC29: 0 | AD29: 0 | AE29: 0 | AF29: 0 | AG29: 0 | AH29: 0 | AI29: 0 | AJ29: 0 | AK29: 0 | AL29: 0 | AM29: 0 | AN29: 0 | AO29: 0 | AP29: 0 | AQ29: 0 | AR29: 0 | AS29: 0 | AT29: 0 | AU29: 0 | AV29: 0 | AW29: 0 | AX29: 0 | AY29: 0 | AZ29: 0 | BA29: 0 | BB29: 0 | BC29: 0 | BD29: 0 | BE29: 0 | BF29: 1 | BG29: 1 | BH29: 1 | BI29: 1 | BJ29: 0 | BK29: 0 | BL29: 0 | BM29: 0 | BN29: 0 | BO29: 0 | BP29: 0 | BQ29: 0 | BR29: 0 | BS29: 0 | BT29: 0 | BU29: 0 | BV29: 0 | BW29: 0 | BX29: 0 | BY29: 0 | BZ29: 0 | CA29: 0 | CB29: 0 | CC29: 0 | CD29: 0 | CE29: 0 | CF29: 0 | CG29: 0 | CH29: 0 | CI29: 0 | CJ29: 0 | CK29: 0 | CL29: 0 | CM29: 0 | CN29: 0 | CO29: 0 | CP29: 0 | CQ29: 2 | CR29: 2 | CS29: 2 | CT29: 2 | CU29: 0 | CV29: 0 | CW29: 0 | CX29: 0 | CY29: 0 | CZ29: 0 | DA29: 0 | DB29: 0 | DC29: 0 | DD29: 0 | DE29: 0 | DF29: 0 | DG29: 0 | DH29: 0 | DI29: 0 | DJ29: 0 | DK29: 0 | DL29: 0 | DM29: 0 | DN29: 0 | DO29: 0 | DP29: 0 | DQ29: 0 | DR29: 0 | DS29: 0 | DT29: 0 | DU29: 0 | DV29: 0 | DW29: 0 | DX29: 0 | DY29: 0 | DZ29: 0 | EA29: 0 | EB29: 0 | EC29: 0 | ED29: 0 | EE29: 0 | EF29: 0 | EG29: 0 | EH29: 0 | EI29: 0 | EJ29: 0 | EK29: 0 | EL29: 0 | EM29: 0 | EN29: 0 | EO29: 0 | EP29: 0 | EQ29: 0 | ER29: 0 | ES29: 0 | ET29: 0 | EU29: 0 | EV29: 0 | EW29: 0 | EX29: 0 | EY29: 0 | EZ29: 0 | FA29: 0 | FB29: 0 | FC29: 0 | FD29: 0 | FE29: 0 | FF29: 0 | FG29: 0 | FH29: 0 | FI29: 0 | FJ29: 0 | FK29: 0 | FL29: 0 | FM29: 0 | FN29: 0 | FO29: 0 | FP29: 0 | FQ29: 0 | FR29: 0 | FS29: 0 | FT29: 0 | FU29: 0 | FV29: 0 | FW29: 0 | FX29: 0 | FY29: 0 | FZ29: 0 | GA29: 0 | GB29: 0 | GC29: 0 | GD29: 0 | GE29: 0 | GF29: 0 | GG29: 0 | GH29: 0 | GI29: 0 | GJ29: 0 | GK29: 0 | GL29: 0 | GM29: 0 | GN29: 0 | GO29: 0 | GP29: 0 | GQ29: 0 | GR29: 0 | GS29: 0 | GT29: 0 | GU29: 0 | GV29: 0 | GW29: 0 | GX29: 0 | GY29: 0 | GZ29: 0 | HA29: 0 | HB29: 0 | HC29: 0 | HD29: 0 | HE29: 0 | HF29: 0 | HG29: 0 | HH29: 0 | HI29: 0 | HJ29: 0 | HK29: 0 | HL29: 0 | HM29: 0 | HN29: 0 | HO29: 0 | HP29: 0 | HQ29: 0 | HR29: 0 | HS29: 0 | HT29: 0 | HU29: 0 | HV29: 0 | HW29: 0 | HX29: 0 | HY29: 0 | HZ29: 0 | IA29: 0 | IB29: 0 | IC29: 0 | ID29: 0 | IE29: 0 | IF29: 0 | IG29: 0 | IH29: 0 | II29: 0 | IJ29: 0 | IK29: 0 | IL29: 0 | IM29: 0 | IN29: 0 | IO29: 0 | IP29: 0 | IQ29: 0 | IR29: 0 | IS29: 0 | IT29: 0 | IU29: 0 | IV29: 0 | IW29: 0 | IX29: 0 | IY29: 0 | IZ29: 0 | JA29: 0 | JB29: 0 | JC29: 0 | JD29: 0 | JE29: 0 | JF29: 0 | JG29: 0 | JH29: 0 | JI29: 0 | JJ29: 0 | JK29: 0 | JL29: 0 | JM29: 0 | JN29: 0 | JO29: 0 | JP29: 0 | JQ29: 0 | JR29: 0 | JS29: 0 | JT29: 0 | JU29: 0 | JV29: 0 | JW29: 0 | JX29: 0 | JY29: 0 | JZ29: 0 | KA29: 0 | KB29: 0 | KC29: 0 | KD29: 0 | KE29: 0 | KF29: 0 | KG29: 0 | KH29: 0 | KI29: 0 | KJ29: 0 | KK29: 0 | KL29: 0 | KM29: 0 | KN29: 0 | KO29: 0 | KP29: 0 | KQ29: 0 | KR29: 0 | KS29: 0 | KT29: 0 | KU29: 0 | KV29: 0 | KW29: 0 | KX29: 0 | KY29: 0 | KZ29: 0 | LA29: 0 | LB29: 0 | LC29: 0 | LD29: 0 | LE29: 0 | LF29: 0 | LG29: 0 | LH29: 0 | LI29: 0 | LJ29: 0 | LK29: 0 | LL29: 0 | LM29: 0 | LN29: 0 | LO29: 0 | LP29: 0 | LQ29: 0 | LR29: 0 | LS29: 0 | LT29: 0 | LU29: 0 | LV29: 0 | LW29: 0 | LX29: 0 | LY29: 0 | LZ29: 0 | MA29: 0 | MB29: 0 | MC29: 0 | MD29: 0 | ME29: 0
G30: 실행
F31: Review 직각도 Setting (Glass 필요) | G31: 계획 | H31: 0 | I31: 0 | J31: 0 | K31: 0 | L31: 0 | M31: 0 | N31: 0 | O31: 0 | P31: 0 | Q31: 0 | R31: 0 | S31: 0 | T31: 0 | U31: 0 | V31: 0 | W31: 0 | X31: 0 | Y31: 0 | Z31: 0 | AA31: 0 | AB31: 0 | AC31: 0 | AD31: 0 | AE31: 0 | AF31: 0 | AG31: 0 | AH31: 0 | AI31: 0 | AJ31: 0 | AK31: 0 | AL31: 0 | AM31: 0 | AN31: 0 | AO31: 0 | AP31: 0 | AQ31: 0 | AR31: 0 | AS31: 0 | AT31: 0 | AU31: 0 | AV31: 0 | AW31: 0 | AX31: 0 | AY31: 0 | AZ31: 0 | BA31: 0 | BB31: 0 | BC31: 0 | BD31: 0 | BE31: 0 | BF31: 0 | BG31: 0 | BH31: 0 | BI31: 0 | BJ31: 1 | BK31: 0 | BL31: 0 | BM31: 0 | BN31: 0 | BO31: 0 | BP31: 0 | BQ31: 0 | BR31: 0 | BS31: 0 | BT31: 0 | BU31: 0 | BV31: 0 | BW31: 0 | BX31: 0 | BY31: 0 | BZ31: 0 | CA31: 0 | CB31: 0 | CC31: 0 | CD31: 0 | CE31: 0 | CF31: 0 | CG31: 0 | CH31: 0 | CI31: 0 | CJ31: 0 | CK31: 0 | CL31: 0 | CM31: 0 | CN31: 0 | CO31: 0 | CP31: 0 | CQ31: 0 | CR31: 0 | CS31: 0 | CT31: 0 | CU31: 0 | CV31: 0 | CW31: 0 | CX31: 0 | CY31: 0 | CZ31: 0 | DA31: 0 | DB31: 0 | DC31: 0 | DD31: 0 | DE31: 0 | DF31: 0 | DG31: 0 | DH31: 0 | DI31: 0 | DJ31: 0 | DK31: 0 | DL31: 0 | DM31: 0 | DN31: 0 | DO31: 0 | DP31: 0 | DQ31: 0 | DR31: 0 | DS31: 0 | DT31: 0 | DU31: 0 | DV31: 0 | DW31: 0 | DX31: 0 | DY31: 0 | DZ31: 0 | EA31: 0 | EB31: 0 | EC31: 0 | ED31: 0 | EE31: 0 | EF31: 0 | EG31: 0 | EH31: 0 | EI31: 0 | EJ31: 0 | EK31: 0 | EL31: 0 | EM31: 0 | EN31: 0 | EO31: 0 | EP31: 0 | EQ31: 0 | ER31: 0 | ES31: 0 | ET31: 0 | EU31: 0 | EV31: 0 | EW31: 0 | EX31: 0 | EY31: 0 | EZ31: 0 | FA31: 0 | FB31: 0 | FC31: 0 | FD31: 0 | FE31: 0 | FF31: 0 | FG31: 0 | FH31: 0 | FI31: 0 | FJ31: 0 | FK31: 0 | FL31: 0 | FM31: 0 | FN31: 0 | FO31: 0 | FP31: 0 | FQ31: 0 | FR31: 0 | FS31: 0 | FT31: 0 | FU31: 0 | FV31: 0 | FW31: 0 | FX31: 0 | FY31: 0 | FZ31: 0 | GA31: 0 | GB31: 0 | GC31: 0 | GD31: 0 | GE31: 0 | GF31: 0 | GG31: 0 | GH31: 0 | GI31: 0 | GJ31: 0 | GK31: 0 | GL31: 0 | GM31: 0 | GN31: 0 | GO31: 0 | GP31: 0 | GQ31: 0 | GR31: 0 | GS31: 0 | GT31: 0 | GU31: 0 | GV31: 0 | GW31: 0 | GX31: 0 | GY31: 0 | GZ31: 0 | HA31: 0 | HB31: 0 | HC31: 0 | HD31: 0 | HE31: 0 | HF31: 0 | HG31: 0 | HH31: 0 | HI31: 0 | HJ31: 0 | HK31: 0 | HL31: 0 | HM31: 0 | HN31: 0 | HO31: 0 | HP31: 0 | HQ31: 0 | HR31: 0 | HS31: 0 | HT31: 0 | HU31: 0 | HV31: 0 | HW31: 0 | HX31: 0 | HY31: 0 | HZ31: 0 | IA31: 0 | IB31: 0 | IC31: 0 | ID31: 0 | IE31: 0 | IF31: 0 | IG31: 0 | IH31: 0 | II31: 0 | IJ31: 0 | IK31: 0 | IL31: 0 | IM31: 0 | IN31: 0 | IO31: 0 | IP31: 0 | IQ31: 0 | IR31: 0 | IS31: 0 | IT31: 0 | IU31: 0 | IV31: 0 | IW31: 0 | IX31: 0 | IY31: 0 | IZ31: 0 | JA31: 0 | JB31: 0 | JC31: 0 | JD31: 0 | JE31: 0 | JF31: 0 | JG31: 0 | JH31: 0 | JI31: 0 | JJ31: 0 | JK31: 0 | JL31: 0 | JM31: 0 | JN31: 0 | JO31: 0 | JP31: 0 | JQ31: 0 | JR31: 0 | JS31: 0 | JT31: 0 | JU31: 0 | JV31: 0 | JW31: 0 | JX31: 0 | JY31: 0 | JZ31: 0 | KA31: 0 | KB31: 0 | KC31: 0 | KD31: 0 | KE31: 0 | KF31: 0 | KG31: 0 | KH31: 0 | KI31: 0 | KJ31: 0 | KK31: 0 | KL31: 0 | KM31: 0 | KN31: 0 | KO31: 0 | KP31: 0 | KQ31: 0 | KR31: 0 | KS31: 0 | KT31: 0 | KU31: 0 | KV31: 0 | KW31: 0 | KX31: 0 | KY31: 0 | KZ31: 0 | LA31: 0 | LB31: 0 | LC31: 0 | LD31: 0 | LE31: 0 | LF31: 0 | LG31: 0 | LH31: 0 | LI31: 0 | LJ31: 0 | LK31: 0 | LL31: 0 | LM31: 0 | LN31: 0 | LO31: 0 | LP31: 0 | LQ31: 0 | LR31: 0 | LS31: 0 | LT31: 0 | LU31: 0 | LV31: 0 | LW31: 0 | LX31: 0 | LY31: 0 | LZ31: 0 | MA31: 0 | MB31: 0 | MC31: 0 | MD31: 0 | ME31: 0
G32: 실행
F33: Vision 셋팅 (Align, Glass 필요) | G33: 계획 | H33: 0 | I33: 0 | J33: 0 | K33: 0 | L33: 0 | M33: 0 | N33: 0 | O33: 0 | P33: 0 | Q33: 0 | R33: 0 | S33: 0 | T33: 0 | U33: 0 | V33: 0 | W33: 0 | X33: 0 | Y33: 0 | Z33: 0 | AA33: 0 | AB33: 0 | AC33: 0 | AD33: 0 | AE33: 0 | AF33: 0 | AG33: 0 | AH33: 0 | AI33: 0 | AJ33: 0 | AK33: 0 | AL33: 0 | AM33: 0 | AN33: 0 | AO33: 0 | AP33: 0 | AQ33: 0 | AR33: 0 | AS33: 0 | AT33: 0 | AU33: 0 | AV33: 0 | AW33: 0 | AX33: 0 | AY33: 0 | AZ33: 0 | BA33: 0 | BB33: 0 | BC33: 0 | BD33: 0 | BE33: 0 | BF33: 0 | BG33: 0 | BH33: 0 | BI33: 0 | BJ33: 0 | BK33: 1 | BL33: 0 | BM33: 0 | BN33: 0 | BO33: 0 | BP33: 0 | BQ33: 0 | BR33: 0 | BS33: 0 | BT33: 0 | BU33: 0 | BV33: 0 | BW33: 0 | BX33: 0 | BY33: 0 | BZ33: 0 | CA33: 0 | CB33: 0 | CC33: 0 | CD33: 0 | CE33: 0 | CF33: 0 | CG33: 0 | CH33: 0 | CI33: 0 | CJ33: 0 | CK33: 0 | CL33: 0 | CM33: 0 | CN33: 0 | CO33: 0 | CP33: 0 | CQ33: 0 | CR33: 0 | CS33: 0 | CT33: 0 | CU33: 0 | CV33: 2 | CW33: 0 | CX33: 0 | CY33: 0 | CZ33: 0 | DA33: 0 | DB33: 0 | DC33: 0 | DD33: 0 | DE33: 0 | DF33: 0 | DG33: 0 | DH33: 0 | DI33: 0 | DJ33: 0 | DK33: 0 | DL33: 0 | DM33: 0 | DN33: 0 | DO33: 0 | DP33: 0 | DQ33: 0 | DR33: 0 | DS33: 0 | DT33: 0 | DU33: 0 | DV33: 0 | DW33: 0 | DX33: 0 | DY33: 0 | DZ33: 0 | EA33: 0 | EB33: 0 | EC33: 0 | ED33: 0 | EE33: 0 | EF33: 0 | EG33: 0 | EH33: 0 | EI33: 0 | EJ33: 0 | EK33: 0 | EL33: 0 | EM33: 0 | EN33: 0 | EO33: 0 | EP33: 0 | EQ33: 0 | ER33: 0 | ES33: 0 | ET33: 0 | EU33: 0 | EV33: 0 | EW33: 0 | EX33: 0 | EY33: 0 | EZ33: 0 | FA33: 0 | FB33: 0 | FC33: 0 | FD33: 0 | FE33: 0 | FF33: 0 | FG33: 0 | FH33: 0 | FI33: 0 | FJ33: 0 | FK33: 0 | FL33: 0 | FM33: 0 | FN33: 0 | FO33: 0 | FP33: 0 | FQ33: 0 | FR33: 0 | FS33: 0 | FT33: 0 | FU33: 0 | FV33: 0 | FW33: 0 | FX33: 0 | FY33: 0 | FZ33: 0 | GA33: 0 | GB33: 0 | GC33: 0 | GD33: 0 | GE33: 0 | GF33: 0 | GG33: 0 | GH33: 0 | GI33: 0 | GJ33: 0 | GK33: 0 | GL33: 0 | GM33: 0 | GN33: 0 | GO33: 0 | GP33: 0 | GQ33: 0 | GR33: 0 | GS33: 0 | GT33: 0 | GU33: 0 | GV33: 0 | GW33: 0 | GX33: 0 | GY33: 0 | GZ33: 0 | HA33: 0 | HB33: 0 | HC33: 0 | HD33: 0 | HE33: 0 | HF33: 0 | HG33: 0 | HH33: 0 | HI33: 0 | HJ33: 0 | HK33: 0 | HL33: 0 | HM33: 0 | HN33: 0 | HO33: 0 | HP33: 0 | HQ33: 0 | HR33: 0 | HS33: 0 | HT33: 0 | HU33: 0 | HV33: 0 | HW33: 0 | HX33: 0 | HY33: 0 | HZ33: 0 | IA33: 0 | IB33: 0 | IC33: 0 | ID33: 0 | IE33: 0 | IF33: 0 | IG33: 0 | IH33: 0 | II33: 0 | IJ33: 0 | IK33: 0 | IL33: 0 | IM33: 0 | IN33: 0 | IO33: 0 | IP33: 0 | IQ33: 0 | IR33: 0 | IS33: 0 | IT33: 0 | IU33: 0 | IV33: 0 | IW33: 0 | IX33: 0 | IY33: 0 | IZ33: 0 | JA33: 0 | JB33: 0 | JC33: 0 | JD33: 0 | JE33: 0 | JF33: 0 | JG33: 0 | JH33: 0 | JI33: 0 | JJ33: 0 | JK33: 0 | JL33: 0 | JM33: 0 | JN33: 0 | JO33: 0 | JP33: 0 | JQ33: 0 | JR33: 0 | JS33: 0 | JT33: 0 | JU33: 0 | JV33: 0 | JW33: 0 | JX33: 0 | JY33: 0 | JZ33: 0 | KA33: 0 | KB33: 0 | KC33: 0 | KD33: 0 | KE33: 0 | KF33: 0 | KG33: 0 | KH33: 0 | KI33: 0 | KJ33: 0 | KK33: 0 | KL33: 0 | KM33: 0 | KN33: 0 | KO33: 0 | KP33: 0 | KQ33: 0 | KR33: 0 | KS33: 0 | KT33: 0 | KU33: 0 | KV33: 0 | KW33: 0 | KX33: 0 | KY33: 0 | KZ33: 0 | LA33: 0 | LB33: 0 | LC33: 0 | LD33: 0 | LE33: 0 | LF33: 0 | LG33: 0 | LH33: 0 | LI33: 0 | LJ33: 0 | LK33: 0 | LL33: 0 | LM33: 0 | LN33: 0 | LO33: 0 | LP33: 0 | LQ33: 0 | LR33: 0 | LS33: 0 | LT33: 0 | LU33: 0 | LV33: 0 | LW33: 0 | LX33: 0 | LY33: 0 | LZ33: 0 | MA33: 0 | MB33: 0 | MC33: 0 | MD33: 0 | ME33: 0
G34: 실행
F35: 광학계 Maint Z축 | G35: 계획 | H35: 0 | I35: 0 | J35: 0 | K35: 0 | L35: 0 | M35: 0 | N35: 0 | O35: 0 | P35: 0 | Q35: 0 | R35: 0 | S35: 0 | T35: 0 | U35: 0 | V35: 0 | W35: 0 | X35: 0 | Y35: 0 | Z35: 0 | AA35: 0 | AB35: 0 | AC35: 0 | AD35: 0 | AE35: 0 | AF35: 0 | AG35: 0 | AH35: 0 | AI35: 0 | AJ35: 0 | AK35: 0 | AL35: 0 | AM35: 0 | AN35: 0 | AO35: 0 | AP35: 0 | AQ35: 0 | AR35: 0 | AS35: 0 | AT35: 0 | AU35: 0 | AV35: 0 | AW35: 0 | AX35: 0 | AY35: 0 | AZ35: 0 | BA35: 0 | BB35: 0 | BC35: 0 | BD35: 0 | BE35: 0 | BF35: 0 | BG35: 0 | BH35: 0 | BI35: 0 | BJ35: 0 | BK35: 0 | BL35: 0 | BM35: 1 | BN35: 1 | BO35: 0 | BP35: 0 | BQ35: 0 | BR35: 0 | BS35: 0 | BT35: 0 | BU35: 0 | BV35: 0 | BW35: 0 | BX35: 0 | BY35: 0 | BZ35: 0 | CA35: 0 | CB35: 0 | CC35: 0 | CD35: 0 | CE35: 0 | CF35: 0 | CG35: 0 | CH35: 0 | CI35: 0 | CJ35: 0 | CK35: 0 | CL35: 0 | CM35: 0 | CN35: 0 | CO35: 0 | CP35: 0 | CQ35: 0 | CR35: 0 | CS35: 0 | CT35: 0 | CU35: 0 | CV35: 0 | CW35: 0 | CX35: 2 | CY35: 2 | CZ35: 0 | DA35: 0 | DB35: 0 | DC35: 0 | DD35: 0 | DE35: 0 | DF35: 0 | DG35: 0 | DH35: 0 | DI35: 0 | DJ35: 0 | DK35: 0 | DL35: 0 | DM35: 0 | DN35: 0 | DO35: 0 | DP35: 0 | DQ35: 0 | DR35: 0 | DS35: 0 | DT35: 0 | DU35: 0 | DV35: 0 | DW35: 0 | DX35: 0 | DY35: 0 | DZ35: 0 | EA35: 0 | EB35: 0 | EC35: 0 | ED35: 0 | EE35: 0 | EF35: 0 | EG35: 0 | EH35: 0 | EI35: 0 | EJ35: 0 | EK35: 0 | EL35: 0 | EM35: 0 | EN35: 0 | EO35: 0 | EP35: 0 | EQ35: 0 | ER35: 0 | ES35: 0 | ET35: 0 | EU35: 0 | EV35: 0 | EW35: 0 | EX35: 0 | EY35: 0 | EZ35: 0 | FA35: 0 | FB35: 0 | FC35: 0 | FD35: 0 | FE35: 0 | FF35: 0 | FG35: 0 | FH35: 0 | FI35: 0 | FJ35: 0 | FK35: 0 | FL35: 0 | FM35: 0 | FN35: 0 | FO35: 0 | FP35: 0 | FQ35: 0 | FR35: 0 | FS35: 0 | FT35: 0 | FU35: 0 | FV35: 0 | FW35: 0 | FX35: 0 | FY35: 0 | FZ35: 0 | GA35: 0 | GB35: 0 | GC35: 0 | GD35: 0 | GE35: 0 | GF35: 0 | GG35: 0 | GH35: 0 | GI35: 0 | GJ35: 0 | GK35: 0 | GL35: 0 | GM35: 0 | GN35: 0 | GO35: 0 | GP35: 0 | GQ35: 0 | GR35: 0 | GS35: 0 | GT35: 0 | GU35: 0 | GV35: 0 | GW35: 0 | GX35: 0 | GY35: 0 | GZ35: 0 | HA35: 0 | HB35: 0 | HC35: 0 | HD35: 0 | HE35: 0 | HF35: 0 | HG35: 0 | HH35: 0 | HI35: 0 | HJ35: 0 | HK35: 0 | HL35: 0 | HM35: 0 | HN35: 0 | HO35: 0 | HP35: 0 | HQ35: 0 | HR35: 0 | HS35: 0 | HT35: 0 | HU35: 0 | HV35: 0 | HW35: 0 | HX35: 0 | HY35: 0 | HZ35: 0 | IA35: 0 | IB35: 0 | IC35: 0 | ID35: 0 | IE35: 0 | IF35: 0 | IG35: 0 | IH35: 0 | II35: 0 | IJ35: 0 | IK35: 0 | IL35: 0 | IM35: 0 | IN35: 0 | IO35: 0 | IP35: 0 | IQ35: 0 | IR35: 0 | IS35: 0 | IT35: 0 | IU35: 0 | IV35: 0 | IW35: 0 | IX35: 0 | IY35: 0 | IZ35: 0 | JA35: 0 | JB35: 0 | JC35: 0 | JD35: 0 | JE35: 0 | JF35: 0 | JG35: 0 | JH35: 0 | JI35: 0 | JJ35: 0 | JK35: 0 | JL35: 0 | JM35: 0 | JN35: 0 | JO35: 0 | JP35: 0 | JQ35: 0 | JR35: 0 | JS35: 0 | JT35: 0 | JU35: 0 | JV35: 0 | JW35: 0 | JX35: 0 | JY35: 0 | JZ35: 0 | KA35: 0 | KB35: 0 | KC35: 0 | KD35: 0 | KE35: 0 | KF35: 0 | KG35: 0 | KH35: 0 | KI35: 0 | KJ35: 0 | KK35: 0 | KL35: 0 | KM35: 0 | KN35: 0 | KO35: 0 | KP35: 0 | KQ35: 0 | KR35: 0 | KS35: 0 | KT35: 0 | KU35: 0 | KV35: 0 | KW35: 0 | KX35: 0 | KY35: 0 | KZ35: 0 | LA35: 0 | LB35: 0 | LC35: 0 | LD35: 0 | LE35: 0 | LF35: 0 | LG35: 0 | LH35: 0 | LI35: 0 | LJ35: 0 | LK35: 0 | LL35: 0 | LM35: 0 | LN35: 0 | LO35: 0 | LP35: 0 | LQ35: 0 | LR35: 0 | LS35: 0 | LT35: 0 | LU35: 0 | LV35: 0 | LW35: 0 | LX35: 0 | LY35: 0 | LZ35: 0 | MA35: 0 | MB35: 0 | MC35: 0 | MD35: 0 | ME35: 0
G36: 실행
